Workbook

Sheet 00 — دليل الاستخدام
A1: البند | B1: الحكم
A2: ◆ INJAZ-MASTER-MAP — ملفُّ التتبعِ المركزيُّ الواحد · الإصدار 1.0 · خطُّ الأساس 2026-08-06
A3: الغرض | B3: أداةُ التتبعِ والتنفيذِ للحزمةِ النهائية — لا وثيقةً خامسةً سردية
A4: المنهج | B4: التجميعُ النهائيُّ لا التصحيحُ الرجعي: لا تُعدَّل وثيقةٌ قديمةٌ ولا يُعاد إصدارُها — تُقرأ وتُوسَم ويُنقل مضمونُها
A5: الحزمةُ النافذة | B5: أربعُ وثائقَ: INJAZ-CORE-01 · INJAZ-FRD-01 · INJAZ-UX-01 · INJAZ-DELIVERY-01 — وهذا الملفُّ الخامسُ أداةً
A6: ◆ الملفاتُ الحيةُ الثلاثة | B6: NAV-09 و SCR-DES-01 و CMP-03 تبقى مستقلةً بأسمائها ومساراتها وبنيتها — يُفهرسها هذا الملفُّ ولا يبتلعها
A7: قاعدةُ الملفِّ الآلي | B7: لا يُنقل ملفٌّ آليٌّ أو تشغيليٌّ قبل حصرِ الأدواتِ التي تقرؤه وتوفيرِ مسارٍ بديلٍ وتشغيلِ مقارنةٍ تثبت صفرَ فرق
A8: حدُّ القطع | B8: كلُّ ما صدر أو استُلم حتى 2026-08-06 23:59 يدخل خطَّ الأساس المجمَّد
A9: ◆ نفاذُ الحكم | B9: لا يُحدَّد بالتاريخ وحدَه — بل بمرتبةِ الوثيقةِ والإصدارِ وحالةِ الاعتمادِ وقرارِ النسخِ وقرارِ المالك الأحدث
A10: توزيعُ المحتوى | B10: الإنسانُ يقرأ الوثائقَ الأربعَ · والتفصيلُ الذريُّ يُبحَث ويُفرَز في أوراق هذا الملف
A11: التوليدُ من الملف | B11: يجوز توليدُ فصلٍ أو مخرَجٍ لإدارةٍ بعينها من هذا الملف — ولا يصير وثيقةً نافذةً مستقلة
A12: ما بعد القطع | B12: يدخل عبر مسار Change Control الرسميِّ في الورقة 02
A13: قاعدةُ الكود | B13: لا يُغيَّر الكودُ قبل إصدار مصفوفة الفجوات — إلا إصلاحًا حرجًا معتمدًا يمنع سلامةَ التجميعِ نفسِه

Sheet 01 — بيان التجميد وسجل الوثائق
A1: # | B1: الرمز | C1: الملف | D1: مسارُ المصدر | E1: sha256 — البصمةُ الحاكمة | F1: md5_legacy | G1: الحجم (بايت) | H1: آخرُ تعديل | I1: الحالة | J1: الصفةُ الدقيقة | K1: الأداةُ التي تقرؤه | L1: سببُ الإدراج أو الاستبعاد | M1: الوجهةُ في الحزمة | N1: الحكمُ والملاحظة
A2: 1 | B2: CMP-01 | C2: CMP-01 — مقارنة السايدبار بنظام الشاشات.xlsx | D2: /mnt/user-data/outputs/CMP-01 — مقارنة السايدبار بنظام الشاشات.xlsx | E2: aa8cf5fef3c241fb7cd8abd347f7902d7fd6885714f638e94f3c48bec756bb16 | F2: ef847f54 | G2: 116769 | H2: 2026-08-04 11:29 | I2: مرجعُ بيانات | J2: ملفُّ تحليلٍ أو مصفوفة | K2: لا أداة | L2: مُدرَجٌ مرجعًا | M2: INJAZ-MASTER-MAP | N2: مُدرَجٌ مرجعًا
A3: 2 | B3: CMP-02 | C3: CMP-02 — مقارنة شجرتَي الأعطال.xlsx | D3: /mnt/user-data/outputs/CMP-02 — مقارنة شجرتَي الأعطال.xlsx | E3: 02ee94e3cd854d6ca5bf0881a2113fa2cc6c0f49a0081aeec603cdbb9de0768b | F3: e7fb9f2f | G3: 20570 | H3: 2026-08-04 12:37 | I3: مرجعُ بيانات | J3: ملفُّ تحليلٍ أو مصفوفة | K3: لا أداة | L3: مُدرَجٌ مرجعًا | M3: INJAZ-MASTER-MAP | N3: مُدرَجٌ مرجعًا
A4: 3 | B4: CMP-03 | C4: CMP-03 — مقارنة أعمدة الشاشات بالنظام الحي.xlsx | D4: /mnt/user-data/outputs/CMP-03 — مقارنة أعمدة الشاشات بالنظام الحي.xlsx | E4: 17c443fc2fa21e0952890e1062c608fd1f19051c5854b84ab8a31436367c3d7a | F4: 6612feb4 | G4: 183256 | H4: 2026-08-04 14:29 | I4: ملفٌّ حيٌّ — يبقى مستقلًّا | J4: مساحةُ قرارٍ وترحيل | K4: محرّكُ قرارِ الأعمدة | L4: مُدرَجٌ ولا يُدمج — أداةٌ آليةٌ تقرؤه | M4: — | N4: مُدرَجٌ ولا يُدمج — أداةٌ آليةٌ تقرؤه
A5: 4 | B5: D-01 | C5: D-01 — دستور منصة إنجاز.docx | D5: /mnt/user-data/outputs/D-01 — دستور منصة إنجاز.docx | E5: feff594eaa8679611cfd0e419553f9aacbf04097bcb278f6926e048e005879ce | F5: 26d88b9c | G5: 58489 | H5: 2026-08-06 07:02 | I5: نافذةٌ — محرّكٌ عرضي | J5: محرّكٌ يخدم كلَّ الإدارات | K5: لا أداة | L5: مُدرَجٌ — تُحيل إليه وثائقُ الإدارات | M5: — | N5: مُدرَجٌ — تُحيل إليه وثائقُ الإدارات
A6: 5 | B6: D-02 | C6: D-02 — المعمارية الشاملة للمنصة.docx | D6: /mnt/user-data/outputs/D-02 — المعمارية الشاملة للمنصة.docx | E6: 6a916866fc85c583a5d25d1720ce0e6072268873e1d3d45c2b673d6c9b59d923 | F6: 278eb9c3 | G6: 50927 | H6: 2026-08-07 05:32 | I6: نافذةٌ — محرّكٌ عرضي | J6: محرّكٌ يخدم كلَّ الإدارات | K6: لا أداة | L6: مُدرَجٌ — تُحيل إليه وثائقُ الإدارات | M6: — | N6: مُدرَجٌ — تُحيل إليه وثائقُ الإدارات
A7: 6 | B7: DEC-SCR-01 | C7: DEC-SCR-01 — ملف القرارات العالقة على الشاشات والأعمدة.xlsx | D7: /mnt/user-data/outputs/DEC-SCR-01 — ملف القرارات العالقة على الشاشات والأعمدة.xlsx | E7: 1fa84d67f941bc0deeb8dac6fed9724fa0295d9c837160a174512d1ea07eb436 | F7: adf3bcff | G7: 491232 | H7: 2026-08-06 13:05 | I7: مرجعُ بيانات | J7: ملفُّ تحليلٍ أو مصفوفة | K7: لا أداة | L7: مُدرَجٌ مرجعًا | M7: INJAZ-MASTER-MAP | N7: مُدرَجٌ مرجعًا
A8: 7 | B8: DIO-01 | C8: DIO-01 — محرّك التصدير والاستيراد والمشاركة.docx | D8: /mnt/user-data/outputs/DIO-01 — محرّك التصدير والاستيراد والمشاركة.docx | E8: a4b84bf98e4ea2d1ec3cd7cc270e85ae5fa4888fbea4bdb0568bbe490476087f | F8: a084ecae | G8: 64372 | H8: 2026-08-07 05:32 | I8: نافذةٌ — محرّكٌ عرضي | J8: محرّكٌ يخدم كلَّ الإدارات | K8: لا أداة | L8: مُدرَجٌ — تُحيل إليه وثائقُ الإدارات | M8: — | N8: مُدرَجٌ — تُحيل إليه وثائقُ الإدارات
A9: 8 | B9: DIO-MAP-01 | C9: DIO-MAP-01 — مصفوفة قابلية التصدير والاستيراد والمشاركة للشاشات.xlsx | D9: /mnt/user-data/outputs/DIO-MAP-01 — مصفوفة قابلية التصدير والاستيراد والمشاركة للشاشات.xlsx | E9: ca41178308936cba91293977ace48b448d443cbdcbd26c02248d951dee492c56 | F9: 1e80642e | G9: 178742 | H9: 2026-08-06 07:04 | I9: مرجعُ بيانات | J9: ملفُّ تحليلٍ أو مصفوفة | K9: لا أداة | L9: مُدرَجٌ مرجعًا | M9: INJAZ-MASTER-MAP | N9: مُدرَجٌ مرجعًا
A10: 9 | B10: DS-01 | C10: DS-01 — النظام التصميمي ومكتبة المكونات.docx | D10: /mnt/user-data/outputs/DS-01 — النظام التصميمي ومكتبة المكونات.docx | E10: ffa3518d00df0cd25c13bedc37070be9bd2c664272eca3364966e225e3a2fac5 | F10: 028f98aa | G10: 70291 | H10: 2026-08-06 15:50 | I10: نافذةٌ — محرّكٌ عرضي | J10: محرّكٌ يخدم كلَّ الإدارات | K10: لا أداة | L10: مُدرَجٌ — تُحيل إليه وثائقُ الإدارات | M10: — | N10: مُدرَجٌ — تُحيل إليه وثائقُ الإدارات
A11: 10 | B11: DS-MAP-01 | C11: DS-MAP-01 — رموز التصميم والمكونات ومسار الهجرة.xlsx | D11: /mnt/user-data/outputs/DS-MAP-01 — رموز التصميم والمكونات ومسار الهجرة.xlsx | E11: 1b60a8ec2e2757f014d7b384a79904e2c25d19f15af90874c6608200a0c2dda1 | F11: cb36a25a | G11: 63726 | H11: 2026-08-06 15:50 | I11: مرجعُ بيانات | J11: ملفُّ تحليلٍ أو مصفوفة | K11: لا أداة | L11: مُدرَجٌ مرجعًا | M11: INJAZ-MASTER-MAP | N11: مُدرَجٌ مرجعًا
A12: 11 | B12: E-01 | C12: E-01 — محرّك الأحداث المالية والأثر المحاسبي.docx | D12: /mnt/user-data/outputs/E-01 — محرّك الأحداث المالية والأثر المحاسبي.docx | E12: 1033cf84008c9a4d0bcd8a44c3f7b228ab16869657ed5e1ccc3fff9cfc708f01 | F12: dcb322e7 | G12: 30313 | H12: 2026-08-07 05:32 | I12: نافذةٌ — محرّكٌ عرضي | J12: محرّكٌ يخدم كلَّ الإدارات | K12: لا أداة | L12: مُدرَجٌ — تُحيل إليه وثائقُ الإدارات | M12: — | N12: مُدرَجٌ — تُحيل إليه وثائقُ الإدارات
A13: 12 | B13: E-02 | C13: E-02 — محرّك دورة الوحدة والتايم شيت.docx | D13: /mnt/user-data/outputs/E-02 — محرّك دورة الوحدة والتايم شيت.docx | E13: f20289c7dd3cd676b63a92d93fe5a3a4c4782025e649c7f7c31f5b0f23469649 | F13: 47d54524 | G13: 34206 | H13: 2026-08-06 07:02 | I13: نافذةٌ — محرّكٌ عرضي | J13: محرّكٌ يخدم كلَّ الإدارات | K13: لا أداة | L13: مُدرَجٌ — تُحيل إليه وثائقُ الإدارات | M13: — | N13: مُدرَجٌ — تُحيل إليه وثائقُ الإدارات
... A64: 63 | B64: WFM-MAP-01 | C64: WFM-MAP-01 — مصفوفة مهام الإدارات ومسارات العمل والطلبات والإنجازات.xlsx | D64: /mnt/user-data/outputs/WFM-MAP-01 — مصفوفة مهام الإدارات ومسارات العمل والطلبات والإنجازات.xlsx | E64: bdad07394445bf3c8575cffc33955c317305fb7c53a3078d182e21c956fd4545 | F64: 25cecd62 | G64: 281786 | H64: 2026-08-05 13:22 | I64: مرجعُ بيانات | J64: ملفُّ تحليلٍ أو مصفوفة | K64: لا أداة | L64: مُدرَجٌ مرجعًا | M64: INJAZ-MASTER-MAP | N64: مُدرَجٌ مرجعًا

Sheet 02 — مسار التغيير
A1: # | B1: الخطوة | C1: ما يُفعل | D1: من ينفّذها | E1: الشاهدُ المطلوب | F1: لا يُنتقل قبلها
A2: 1 | B2: استلامُ مادةٍ بعد القطع | C2: تُسجَّل في هذه الورقةِ بتاريخها ومصدرِها ومقدّمِها — ولا تُدمج في الحزمة تلقائيًّا | D2: مكتبُ الهندسة | E2: سطرٌ في السجلِّ بمعرّفٍ وتاريخٍ | F2: الفحصِ
A3: 2 | B3: فحصُ المرتبةِ والنفاذ | C3: أالمادةُ أعلى مرتبةً من الحكمِ النافذِ الحالي؟ أمعتمدةٌ أم نافذ؟ | D3: مكتبُ الهندسة | E3: حكمٌ صريحٌ: تنسخ أم تُنسَخ أم تُهمَل | F3: تقديرِ الأثر
A4: 3 | B4: تقديرُ الأثر | C4: أيَّ فصلٍ في أيِّ وثيقةٍ تمسّ؟ وأيَّ ورقةٍ في هذا الملف؟ وأيَّ كودٍ حيّ؟ | D4: مكتبُ الهندسة + المالكُ المختص | E4: مصفوفةُ أثرٍ بثلاثة أعمدة | F4: اعتمادِ المالك
A5: 4 | B5: اعتمادُ المالك | C5: يوقّع الرئيسُ التنفيذيُّ أو نائبُه المختصُّ على الإدماج | D5: الرئيسُ التنفيذيُّ أو نائبُه | E5: اعتمادٌ موثَّقٌ بتاريخه | F5: الإدماج
A6: 5 | B6: الإدماجُ في الحزمة | C6: يُنقل الحكمُ إلى فصله ويُسجَّل في الورقة 03 بمصدرِه وتاريخِه | D6: مكتبُ الهندسة | E6: سطرٌ في سجل الأحكامِ بمرجعه | F6: إصدارِ النسخة
A7: 6 | B7: إصدارُ نسخةٍ جديدة | C7: يُرفع رقمُ الوثيقةِ المتأثرةِ وتُحدَّث بصمتُها في الورقة 01 | D7: مكتبُ الهندسة | E7: بصمةٌ جديدةٌ في بيان التجميد | F7: —
A8: ◆ | B8: الحكم | C8: لا مادةَ تدخل الحزمةَ إلا بالخطوات الستِّ كاملةً — والإدماجُ المباشرُ يُبطل خطَّ الأساس | D8: — | E8: — | F8: —

Sheet 03 — سجل الأحكام النهائية
A1: # | B1: معرّفُ الحكم | C1: نصُّ الحكم | D1: الوثيقةُ الأصلية | E1: القسم | F1: المجالُ أو الإدارة | G1: الحكمُ الأحدثُ الحاكم | H1: canonical_home_document | I1: canonical_home_section | J1: referenced_by_documents | K1: اختبارُ القبول | L1: أمطبَّقٌ في الكود | M1: حالةُ النفاذ
A2: 1 | B2: ORG-001 | C2: منصة إنجاز نشأت نظامًا داخليًا لإدارة شركة إكوبيشن للتشغيل، المتخصصة في تشغيل المعدات والمتحركات في قطاع التعدين والمناجم والمحاجر، وتتحول إلى نواة منصة مؤسسية قابلة للتشغيل بوصفها SaaS متعدد الشركات. | D2: SRC-001 | E2: أولًا | F2: ORG | G2: لا معارض — نافذ بنصّه | H2: INJAZ-CORE-01 | I2: الفصلُ ١ — الدستور | J2: FRD-01 · UX-01 · DELIVERY-01 — تُحيل ولا تعيد الكتابة | K2: اختبارُ وجودٍ وسلوك: بمعطى بيئةٍ مهيَّأةٍ لـ«منصة إنجاز نشأت نظامًا داخليًا لإدارة شركة إكوبيشن ل…» · وعند تنفيذ السيناريو الموصوف · فإن السلوكَ يطابق النصَّ ويُوثَّق الشاهدُ بلقطةٍ أو سجل | L2: غير مقيس — يُملأ عند مراجعة الكود | M2: نافذ
A3: 2 | B3: ORG-002 | C3: القطاعات المخدومة: تشغيل المعدات الثقيلة / التعدين والمحاجر / إدارة المعدات والموردين / المقاولات والخدمات التشغيلية / إدارة المشاريع والمواقع / القوى التشغيلية والمشغلين / الصيانة والمخازن والمشتريات / النقل والترحيل / العقود والاستحقاقات والتسويات / الإدارة المالية والتمويل والملكية / الحوكمة والالتزام والبلاغات. | D3: SRC-001 | E3: أولًا | F3: ORG | G3: لا معارض — نافذ بنصّه | H3: INJAZ-CORE-01 | I3: الفصلُ ١ — الدستور | J3: FRD-01 · UX-01 · DELIVERY-01 — تُحيل ولا تعيد الكتابة | K3: اختبارُ وجودٍ وسلوك: بمعطى بيئةٍ مهيَّأةٍ لـ«تشغيل المعدات الثقيلة / التعدين والمحاجر / إدارة الم…» · وعند تنفيذ السيناريو الموصوف · فإن السلوكَ يطابق النصَّ ويُوثَّق الشاهدُ بلقطةٍ أو سجل | L3: غير مقيس — يُملأ عند مراجعة الكود | M3: نافذ
A4: 3 | B4: ORG-003 | C4: الشريحة المستهدفة تشمل الشركات الصغيرة والمتوسطة والكبيرة معًا؛ ولا يجوز تصميم النظام لفئة واحدة منها. | D4: SRC-001 | E4: أولًا | F4: ORG | G4: لا معارض — نافذ بنصّه | H4: INJAZ-CORE-01 | I4: الفصلُ ١ — الدستور | J4: FRD-01 · UX-01 · DELIVERY-01 — تُحيل ولا تعيد الكتابة | K4: اختبارُ منع: بمعطى محاولةٍ تخالف «الشريحة المستهدفة تشمل الشركات الصغيرة والمتوسطة وال…» · وعند تنفيذها · فإن الخادمَ يرفض برمزٍ وسببٍ ويُسجَّل الرفضُ بالمستخدم والوقت | L4: غير مقيس — يُملأ عند مراجعة الكود | M4: نافذ
A5: 4 | B5: ORG-004 | C5: الجهات التابعة للرئيس التنفيذي مباشرة (تسع): إدارة التشغيل / إدارة المبيعات والعقود / إدارة الموردين / الإدارة المالية والخزينة / إدارة التمويل والملكية / إدارة الأسطول / إدارة الموارد البشرية / إدارة الحوكمة والالتزام / مركز البلاغات. | D5: SRC-001 | E5: تاسعًا | F5: ORG | G5: لا معارض — نافذ بنصّه | H5: INJAZ-CORE-01 | I5: الفصلُ ١ — الدستور | J5: FRD-01 · UX-01 · DELIVERY-01 — تُحيل ولا تعيد الكتابة | K5: اختبارُ وجودٍ وسلوك: بمعطى بيئةٍ مهيَّأةٍ لـ«إدارة التشغيل / إدارة المبيعات والعقود / إدارة المور…» · وعند تنفيذ السيناريو الموصوف · فإن السلوكَ يطابق النصَّ ويُوثَّق الشاهدُ بلقطةٍ أو سجل | L5: غير مقيس — يُملأ عند مراجعة الكود | M5: نافذ
A6: 5 | B6: ORG-005 | C6: الإدارات التشغيلية التابعة لمدير التشغيل (ست): إدارات المواقع وعلى رأس كل موقع مدير موقع / إدارة الصيانة / إدارة القوى التشغيلية / إدارة المشتريات / إدارة المخازن / إدارة النقل والترحيل. | D6: SRC-001 | E6: تاسعًا | F6: ORG | G6: لا معارض — نافذ بنصّه | H6: INJAZ-CORE-01 | I6: الفصلُ ١ — الدستور | J6: FRD-01 · UX-01 · DELIVERY-01 — تُحيل ولا تعيد الكتابة | K6: اختبارُ وجودٍ وسلوك: بمعطى بيئةٍ مهيَّأةٍ لـ«إدارات المواقع وعلى رأس كل موقع مدير موقع / إدارة ال…» · وعند تنفيذ السيناريو الموصوف · فإن السلوكَ يطابق النصَّ ويُوثَّق الشاهدُ بلقطةٍ أو سجل | L6: غير مقيس — يُملأ عند مراجعة الكود | M6: نافذ
A7: 6 | B7: ORG-007 | C7: يجب الحفاظ على التمييز بين ثمانية مفاهيم لا تُخلط: الإدارة التنظيمية / باب التنقل / مجموعة الشاشات / المسمى الوظيفي / التكليف الموقعي / الدور والصلاحية / الشاشة المالكة / شاشة العرض أو زاوية الاطلاع. | D7: SRC-001 | E7: تاسعًا | F7: ORG | G7: لا معارض — نافذ بنصّه | H7: INJAZ-CORE-01 | I7: الفصلُ ١ — الدستور | J7: FRD-01 · UX-01 · DELIVERY-01 — تُحيل ولا تعيد الكتابة | K7: اختبارُ منع: بمعطى محاولةٍ تخالف «الإدارة التنظيمية / باب التنقل / مجموعة الشاشات / ال…» · وعند تنفيذها · فإن الخادمَ يرفض برمزٍ وسببٍ ويُسجَّل الرفضُ بالمستخدم والوقت | L7: غير مقيس — يُملأ عند مراجعة الكود | M7: نافذ
A8: 7 | B8: ORG-008 | C8: الهيكل التنظيمي أعلاه هو نقطة الانطلاق الملزمة، ولا يُعدَّل إلا إذا ظهر قرار أحدث صريح داخل الوثائق. | D8: SRC-001 | E8: تاسعًا | F8: ORG | G8: لا معارض — نافذ بنصّه | H8: INJAZ-CORE-01 | I8: الفصلُ ١ — الدستور | J8: FRD-01 · UX-01 · DELIVERY-01 — تُحيل ولا تعيد الكتابة | K8: اختبارُ منع: بمعطى محاولةٍ تخالف «الهيكل التنظيمي أعلاه هو نقطة الانطلاق الملزمة» · وعند تنفيذها · فإن الخادمَ يرفض برمزٍ وسببٍ ويُسجَّل الرفضُ بالمستخدم والوقت | L8: غير مقيس — يُملأ عند مراجعة الكود | M8: نافذ
A9: 8 | B9: DOC-001 | C9: التوقف عن إضافة وثائق صغيرة متفرقة نهائيًا. | D9: SRC-001 | E9: أولًا | F9: DOC | G9: لا معارض — نافذ بنصّه | H9: INJAZ-CORE-01 | I9: الفصلُ ١ — الدستور | J9: FRD-01 · UX-01 · DELIVERY-01 — تُحيل ولا تعيد الكتابة | K9: اختبارُ وجودٍ وسلوك: بمعطى بيئةٍ مهيَّأةٍ لـ«التوقف عن إضافة وثائق صغيرة متفرقة نهائيًا» · وعند تنفيذ السيناريو الموصوف · فإن السلوكَ يطابق النصَّ ويُوثَّق الشاهدُ بلقطةٍ أو سجل | L9: غير مقيس — يُملأ عند مراجعة الكود | M9: نافذ
A10: 9 | B10: DOC-002 | C10: إعادة بناء المنظومة التوثيقية كأن منصة إنجاز صُممت من البداية وفق آخر ما استقر عليه المشروع. | D10: SRC-001 | E10: أولًا | F10: DOC | G10: لا معارض — نافذ بنصّه | H10: INJAZ-CORE-01 | I10: الفصلُ ١ — الدستور | J10: FRD-01 · UX-01 · DELIVERY-01 — تُحيل ولا تعيد الكتابة | K10: اختبارُ وجودٍ وسلوك: بمعطى بيئةٍ مهيَّأةٍ لـ«إعادة بناء المنظومة التوثيقية كأن منصة إنجاز صُممت م…» · وعند تنفيذ السيناريو الموصوف · فإن السلوكَ يطابق النصَّ ويُوثَّق الشاهدُ بلقطةٍ أو سجل | L10: غير مقيس — يُملأ عند مراجعة الكود | M10: نافذ
A11: 10 | B11: DOC-003 | C11: المهمة ليست تلخيصًا ولا دمجًا ميكانيكيًا ولا إعادة كتابة لآخر نسخة فقط. | D11: SRC-001 | E11: ثانيًا | F11: DOC | G11: لا معارض — نافذ بنصّه | H11: INJAZ-CORE-01 | I11: الفصلُ ١ — الدستور | J11: FRD-01 · UX-01 · DELIVERY-01 — تُحيل ولا تعيد الكتابة | K11: اختبارُ وجودٍ وسلوك: بمعطى بيئةٍ مهيَّأةٍ لـ«المهمة ليست تلخيصًا ولا دمجًا ميكانيكيًا ولا إعادة ك…» · وعند تنفيذ السيناريو الموصوف · فإن السلوكَ يطابق النصَّ ويُوثَّق الشاهدُ بلقطةٍ أو سجل | L11: غير مقيس — يُملأ عند مراجعة الكود | M11: نافذ
A12: 11 | B12: DOC-004 | C12: استخراج كل قاعدة وميزة وشاشة ودورة عمل واعتماد وحارس وقرار من كل وثيقة. | D12: SRC-001 | E12: ثانيًا | F12: DOC | G12: لا معارض — نافذ بنصّه | H12: INJAZ-CORE-01 | I12: الفصلُ ١ — الدستور | J12: FRD-01 · UX-01 · DELIVERY-01 — تُحيل ولا تعيد الكتابة | K12: اختبارُ ظهور: بمعطى مستخدمٍ داخلَ النطاق وآخرَ خارجه لـ«استخراج كل قاعدة وميزة وشاشة ودورة عمل واعتماد وحارس…» · وعند فتح الشاشة · فإن الأولَ يرى نطاقَه والثانيَ لا يُصيَّر له العنصرُ ولا يُرسَل في الاستجابة | L12: غير مقيس — يُملأ عند مراجعة الكود | M12: نافذ
A13: 12 | B13: DOC-005 | C13: معرفة علاقة كل معلومة ببقية المنظومة. | D13: SRC-001 | E13: ثانيًا | F13: DOC | G13: لا معارض — نافذ بنصّه | H13: INJAZ-CORE-01 | I13: الفصلُ ١ — الدستور | J13: FRD-01 · UX-01 · DELIVERY-01 — تُحيل ولا تعيد الكتابة | K13: اختبارُ وجودٍ وسلوك: بمعطى بيئةٍ مهيَّأةٍ لـ«معرفة علاقة كل معلومة ببقية المنظومة» · وعند تنفيذ السيناريو الموصوف · فإن السلوكَ يطابق النصَّ ويُوثَّق الشاهدُ بلقطةٍ أو سجل | L13: غير مقيس — يُملأ عند مراجعة الكود | M13: نافذ
... A5531: 5530 | B5531: GEN-0039 | C5531: ◆ لكل إدارةٍ مساحةُ حوكمةٍ نطاقيةٌ تعرض هيكلَها وأدوارَها وتفويضاتِها وتعارضاتِ واجباتها ومراجعاتِ وصولها — منظرًا على المصادرِ المركزيةِ لا نظامًا مستقلًّا. | D5531: INJAZ-CORE-01 · الفصلُ التاسع — المتطلباتُ العامةُ الملزمةُ لكلِّ شاشة | E5531: §المخاطر والحوكمة | F5531: GEN | G5531: قرار مالك موقَّع — نافذ | H5531: INJAZ-MASTER-MAP | I5531: ورقةُ أحكامٍ غيرِ مصنَّفة | J5531: — | K5531: اختبارُ نطاق: تعرض نطاقَ الإدارةِ وحدَه بحسب الصلاحية | L5531: مطلوب — يُقاس من النظام الحي | M5531: نافذ

Sheet 04 — مصفوفة النسخ والاستبدال
A1: # | B1: الوثيقةُ الأقدم | C1: الحكمُ فيها | D1: الوثيقةُ الأحدث | E1: الحكمُ الناسخ | F1: نوعُ العلاقة | G1: الأساسُ | H1: الحالة
A2: 1 | B2: SCR-DES-01 · الأعمدةُ الحاكمة | C2: تُكتب في كل شاشةٍ على حدة | D2: D-02 النمط AR-03 | E2: تُحقن من طبقةٍ مشتركةٍ واحدة | F2: نسخٌ جزئيّ | G2: المعماريةُ أعلى مرتبةً من ملفِّ التصميم | H2: نافذٌ — والتنفيذُ في MG-2
A3: 2 | B3: E-03 المعيارُ الرابع | C3: الأعمدةُ الحاكمةُ سبعةٌ إلزامية | D3: DS-01 بوابةُ التكافؤ | E3: ثلاثةَ عشرَ عمودًا حاكمًا مصنَّفةً ثلاثةَ أصناف | F3: توسيعٌ لا نسخ | G3: الأحدثُ يفصّل ولا يخالف | H3: نافذان معًا
A4: 3 | B4: E-03 §المعيارُ الخامسُ فقط | C4: طقمُ حالاتٍ موحَّدٌ بسبع | D4: DS-01 المبدأ DS-10 | E4: خمسةُ محاورَ مستقلةٍ يركّبها CM-00 | F4: نسخٌ على مستوى القسم — PARTIAL | G4: النموذجُ القديمُ في قسمٍ بعينِه يخلط محاورَ مختلفة · ◆ وبقيةُ E-03 نافذةٌ كلُّها ولا تُمسّ | H4: القسمُ منسوخٌ — وE-03 يبقى أعلى في ماذا تعرض ومن يرى
A5: 4 | B5: UX-AUD-01 §حالاتُ الشاشة | C5: قائمةٌ واحدةٌ بسبعِ حالات | D5: DS-01 المبدأ DS-10 | E5: خمسةُ محاورَ مستقلة | F5: نسخٌ على مستوى القسم — PARTIAL | G5: محكومٌ في هذه الوثيقة · وبقيةُ UX-AUD-01 نافذة | H5: القسمُ منسوخٌ لا الوثيقة
A6: 5 | B6: DEC-SCR-01 v0.6 | C6: القرارُ على العمودِ بالاسم | D6: DEC-SCR-01 v0.7 | E6: معرّفٌ دلاليٌّ لكل شاشةٍ ولا يُفترض التكافؤ | F6: نسخُ إصدارٍ — VERSION | G6: حادثةُ «الوحدة» أثبتت الخطأ · والإصدارُ الأحدثُ من الوثيقةِ نفسِها | H6: v0.7 نافذٌ و v0.6 تاريخي
A7: 6 | B7: orgmodel v1 §علاقةُ الموقع | C7: إدارةُ الموقعِ تتبع الإداراتِ التشغيليةَ الخمس | D7: orgmodel v2 · L4 الفرعان | E7: مديرو المواقعِ يوازون الإداراتَ التشغيليةَ تحت مدير التشغيل | F7: ◆ نسخٌ كامل للعلاقة | G7: مديرُ الموقعِ ليس موظفًا تحت خمسةِ مدراء | H7: v2 نافذٌ — والأثرُ على parent_org_unit والموافقاتِ والصلاحيات
A8: 7 | B8: DIO-01 v0.9 §المشاركة | C8: ستةُ مستوياتٍ للجميع | D8: DEC-08 التوصية | E8: ثلاثةُ مستوياتٍ للخارجيِّ بلا اعتماد | F8: تخصيصٌ | G8: الاعتمادُ لا يُمنح لمن ليس في الشركة | H8: توصيةٌ تنتظر الاعتماد
A9: 8 | B9: قوائمُ الأفعالِ القديمة | C9: رمزٌ قصيرٌ بلا نطاق | D9: التدقيقُ العالميُّ — الورقة 07 | E9: نمط domain.resource.action | F9: نسخٌ بـalias | G9: أربعةُ رموزٍ تحمل معنيين | H9: ◆ حاجبٌ حتى الإصلاح
A10: 9 | B10: «الرئيس التنفيذي» | C10: المسمّى القياديُّ القديم | D10: قرارُ المالك | E10: الرئيسُ التنفيذيُّ وثلاثةُ نواب | F10: نسخٌ كامل | G10: قرارُ مالكٍ أحدث | H10: نافذٌ — وطُبِّق في 29 وثيقة

Sheet 05 — الإدارات والدورات
A1: الرتبة | B1: الطبقة | C1: الإدارة | D1: التابعُ له | E1: المراحل | F1: المجموعات | G1: ظهورُ الشاشات | H1: الشاشاتُ المملوكة | I1: الأفعال | J1: الفصلُ في FRD | K1: الحكمُ والملاحظة
A2: 1 | B2: L1+L2 | C2: مكتبُ الرئيس التنفيذي والنواب | D2: — | E2: 9 | F2: 18 | G2: 25 | H2: 7 | I2: 10 | J2: — | K2: أعلى الهيكل — الرئيسُ التنفيذيُّ وثلاثةُ نواب
A3: 2 | B3: L3 | C3: إدارة التشغيل | D3: نائبُ العمليات | E3: 9 | F3: 22 | G3: 42 | H3: 8 | I3: 14 | J3: الفصلُ ٤ — إدارة التشغيل | K3: متوازيةٌ — وتحتها فرعان متوازيان: الإداراتُ التشغيليةُ ومديرو المواقع
A4: 3 | B4: L3 | C4: المبيعات والعقود | D4: نائبُ الشؤون المالية والاستثمار | E4: 10 | F4: 26 | G4: 42 | H4: 22 | I4: 27 | J4: الفصلُ ٥ — المبيعات والعقود | K4: متوازيةٌ — تملك العقدَ والتغطيةَ والأسعار
A5: 4 | B5: L3 | C5: إدارة الموردين | D5: نائبُ الشؤون المالية والاستثمار | E5: 11 | F5: 29 | G5: 45 | H5: 18 | I5: 24 | J5: الفصلُ ٦ — إدارة الموردين | K5: متوازيةٌ — تملك عقدَ الموردِ والحصصَ والحاويات
A6: 5 | B6: L3 | C6: إدارة الأسطول | D6: نائبُ الشؤون المالية والاستثمار | E6: 10 | F6: 23 | G6: 37 | H6: 13 | I6: 17 | J6: الفصلُ ٧ — إدارة الأسطول | K6: متوازيةٌ — تملك الأصلَ والوثائقَ والعدّادات
A7: 6 | B7: L3 | C7: المالية والخزينة | D7: نائبُ الشؤون المالية والاستثمار | E7: 11 | F7: 36 | G7: 53 | H7: 28 | I7: 35 | J7: الفصلُ ٨ — المالية والخزينة | K7: متوازيةٌ — تملك الدفاترَ والذممَ والخزينة
A8: 7 | B8: L3 | C8: التمويل والملكية | D8: نائبُ الشؤون المالية والاستثمار | E8: 9 | F8: 21 | G8: 33 | H8: 14 | I8: 18 | J8: الفصلُ ٩ — التمويل والملكية | K8: متوازيةٌ — تملك الملكيةَ وأنماطَ التمويل
A9: 8 | B9: L3 | C9: إدارة المشتريات المركزية | D9: نائبُ الشؤون المالية والاستثمار | E9: ◆ لا دورة | F9: ◆ لا مجموعات | G9: ◆ لا شاشات | H9: ◆ لا شاشات | I9: ◆ لا أفعال | J9: ◆ لا فصلَ بعد | K9: ◆ إدارةٌ مستكملة: الشراءُ الاستراتيجيُّ والاعتماداتُ فوق سقفِ التشغيليةِ والعقودُ الإطارية
A10: 9 | B10: L3 | C10: الموارد البشرية | D10: نائبُ الشؤون الإدارية والحوكمة | E10: 11 | F10: 23 | G10: 34 | H10: 13 | I10: 17 | J10: الفصلُ ١٠ — الموارد البشرية | K10: متوازيةٌ — تملك العلاقةَ الوظيفيةَ والمسيّر
A11: 10 | B11: L3 | C11: شؤونُ العاملين بالمشروعات | D11: نائبُ الشؤون الإدارية والحوكمة | E11: ◆ لا دورة | F11: ◆ لا مجموعات | G11: ◆ لا شاشات | H11: ◆ لا شاشات | I11: ◆ لا أفعال | J11: ◆ لا فصلَ بعد | K11: ◆ وحدةٌ مستكملة: العقودُ المشروعيةُ المؤقتةُ والتعبئةُ والتسريحُ الميداني
A12: 11 | B12: L3 | C12: إدارة المخاطر المؤسسية | D12: ◆ الرئيسُ التنفيذيُّ مباشرةً | E12: 9 | F12: 9 | G12: 18 | H12: 20 | I12: 36 | J12: — | K12: ◆ تتبع الرئيسَ التنفيذيَّ مباشرةً في طبقةٍ موازيةٍ للحوكمةِ والالتزام — فاستقلالُها عمّن تراقبهم شرطُ فاعليتها · وتملك المنهجَ والقياسَ والتحدي والتجميعَ والتصعيدَ لا ملكيةَ مخاطرِ الإدارات
A13: 12 | B13: L3 | C13: الحوكمة والالتزام | D13: ◆ الرئيسُ التنفيذيُّ مباشرةً | E13: 11 | F13: 32 | G13: 41 | H13: 33 | I13: 41 | J13: الفصلُ ١١ — الحوكمة والالتزام | K13: ◆ رقابيةٌ تتبع الرئيسَ مباشرةً — تملك الصلاحياتِ والاستثناءاتِ وسجلَّ التدقيقِ وفصلَ الواجبات · ولا تملك منهجَ المخاطرِ ولا قياسَها
A14: 13 | B14: L3 | C14: مركز البلاغات | D14: نائبُ الشؤون الإدارية والحوكمة | E14: 10 | F14: 15 | G14: 21 | H14: 13 | I14: 19 | J14: الفصلُ ١٢ — مركز البلاغات | K14: ◆ مركزٌ رقابيٌّ وخدميٌّ عابرٌ للإدارات — لا إدارةً مركزيةً بالمعنى نفسِه للمالية
A15: 14 | B15: L4 · الفرعُ الأول | C15: إدارة الصيانة | D15: مديرُ التشغيل | E15: 9 | F15: 19 | G15: 34 | H15: 8 | I15: 14 | J15: الفصلُ ١٣ — إدارة الصيانة | K15: تشغيليةٌ مركزيةٌ — تملك الحكمَ الفنيَّ والجاهزيةَ وشجرةَ الأعطال · ◆ توازي مديري المواقعِ ولا تعلوهم
A16: 15 | B16: L4 · الفرعُ الأول | C16: القوى التشغيلية | D16: مديرُ التشغيل | E16: 10 | F16: 24 | G16: 37 | H16: 11 | I16: 15 | J16: الفصلُ ١٤ — القوى التشغيلية | K16: تشغيليةٌ مركزيةٌ — تملك المشغّلينَ وتأهيلَهم · ◆ توازي مديري المواقع
A17: 16 | B17: L4 · الفرعُ الأول | C17: النقل والترحيل | D17: مديرُ التشغيل | E17: 9 | F17: 14 | G17: 23 | H17: 9 | I17: 13 | J17: الفصلُ ١٥ — النقل والترحيل | K17: تشغيليةٌ مركزيةٌ — تملك أوامرَ الترحيلِ ووسائلَ النقل · ◆ توازي مديري المواقع
A18: 17 | B18: L4 · الفرعُ الأول | C18: إدارة المشتريات التشغيلية | D18: مديرُ التشغيل | E18: 8 | F18: 13 | G18: 23 | H18: 6 | I18: 13 | J18: — | K18: تشغيليةٌ مركزيةٌ — تملك الاحتياجَ التشغيليَّ وأمرَ الشراءِ داخلَ سقفها · ◆ توازي مديري المواقع
A19: 18 | B19: L4 · الفرعُ الأول | C19: إدارة المخازن | D19: مديرُ التشغيل | E19: 8 | F19: 16 | G19: 25 | H19: 11 | I19: 16 | J19: الفصلُ ١٧ — إدارة المخازن | K19: تشغيليةٌ مركزيةٌ — تملك الرصيدَ والتقييمَ والجرد · ◆ توازي مديري المواقع
A20: 19 | B20: L4 · الفرعُ الثاني | C20: إدارة الموقع | D20: مديرُ التشغيل | E20: 11 | F20: 23 | G20: 41 | H20: 11 | I20: 23 | J20: — | K20: ◆ وحدةُ موقعٍ تتبع مديرَ التشغيلِ مباشرةً — وتوازي الإداراتَ التشغيليةَ الخمسَ ولا تتبعها · وأعلى سلطةٍ ميدانيةٍ في موقعها
A21: 20 | B21: — | C21: مساحة عملي | D21: عرضيةٌ لكل الأدوار | E21: 5 | F21: 7 | G21: 13 | H21: 10 | I21: 10 | J21: — | K21: ◆ ليست إدارةً ولا وحدةً — واجهةٌ عرضيةٌ بلا مديرٍ ولا ميزانيةٍ ولا خطِّ تبعية
A22: — | B22: — | C22: الإجمالي | D22: — | E22: 145 | F22: 345 | G22: 553 | H22: 203 | I22: 246 | J22: — | K22: الطبقاتُ الستُّ في الورقة 12

Sheet 06 — سجل الشاشات
A1: # | B1: الإدارةُ المالكة | C1: الملف | D1: اسمُ الشاشة | E1: المرحلة | F1: المجموعة | G1: الأعمدة | H1: أطويلة | I1: الأفعال | J1: العارضون | K1: حقولٌ حساسة | L1: المناظر | M1: الفصلُ في UX
A2: 1 | B2: الإدارة التنفيذية | C2: ceo_approvals.php | D2: اعتمادات الرئيس التنفيذي | E2: ثانيًا: الاعتمادات العليا | F2: صندوق الاعتمادات العليا | G2: 23 | H2: نعم | I2: 1 | J2: 7 | K2: 1 | L2: مطلوبة | M2: الفصلُ ٢ — سجلُّ الشاشات
A3: 2 | B3: الإدارة التنفيذية | C3: ceo_contracts.php | D3: العقود والالتزامات المحجوزة أو المصعَّدة | E3: ثالثًا: العقودُ والالتزاماتُ المحجوزةُ أو المصعَّدةُ للرئيس | F3: توقيع العقود | G3: 30 | H3: نعم | I3: 1 | J3: 4 | K3: 2 | L3: مطلوبة | M3: الفصلُ ٢ — سجلُّ الشاشات
A4: 3 | B4: الإدارة التنفيذية | C4: risk_dept_ceo.php | D4: المخاطر المؤسسية | E4: مخاطرُ الإدارة | F4: مخاطرُ إدارتي | G4: 22 | H4: نعم | I4: 3 | J4: 1 | K4: 1 | L4: مطلوبة | M4: الفصلُ ٢ — سجلُّ الشاشات
A5: 4 | B5: الإدارة التنفيذية | C5: ceo_risk.php | D5: المخاطر والقرارات العليا | E5: خامسًا: المخاطر والحسم | F5: المخاطر والقرارات العليا | G5: 19 | H5: لا | I5: 1 | J5: 1 | K5: 0 | L5: غيرُ لازمة | M5: الفصلُ ٢ — سجلُّ الشاشات
A6: 5 | B6: الإدارة التنفيذية | C6: gov_dept_ceo.php | D6: حوكمة مكتبُ الرئيس التنفيذي والنواب | E6: — | F6: — | G6: 15 | H6: لا | I6: 2 | J6: 1 | K6: 1 | L6: غيرُ لازمة | M6: الفصلُ ٢ — سجلُّ الشاشات
A7: 6 | B7: الإدارة التنفيذية | C7: project_charter.php | D7: قرار فتح مشروع جديد | E7: رابعًا: فتح المشاريع | F7: قرار فتح مشروع | G7: 31 | H7: نعم | I7: 1 | J7: 6 | K7: 3 | L7: مطلوبة | M7: الفصلُ ٢ — سجلُّ الشاشات
A8: 7 | B8: الإدارة التنفيذية | C8: ceo_board.php | D8: لوحة الرئيس التنفيذي | E8: لوحة الإدارة التنفيذية | F8: المؤشرات العليا | G8: 16 | H8: لا | I8: 1 | J8: 0 | K8: 3 | L8: غيرُ لازمة | M8: الفصلُ ٢ — سجلُّ الشاشات
A9: 8 | B9: إدارة التشغيل | C9: unit_assign.php | D9: إسناد المعدات للوحدات | E9: ثانيًا: توزيع الموارد | F9: الإسناد للوحدات | G9: 27 | H9: نعم | I9: 1 | J9: 3 | K9: 1 | L9: مطلوبة | M9: الفصلُ ٢ — سجلُّ الشاشات
A10: 9 | B10: إدارة التشغيل | C10: unit_perf.php | D10: الأداء الشهري للوحدة | E10: رابعًا: متابعة الانحراف | F10: الأداء الشهري | G10: 33 | H10: نعم | I10: 1 | J10: 3 | K10: 3 | L10: مطلوبة | M10: الفصلُ ٢ — سجلُّ الشاشات
A11: 10 | B11: إدارة التشغيل | C11: monthly_close.php | D11: الإقفال الشهري للوحدة | E11: سابعًا: إقفال اليوم | F11: الإقفال | G11: 33 | H11: نعم | I11: 1 | J11: 4 | K11: 3 | L11: مطلوبة | M11: الفصلُ ٢ — سجلُّ الشاشات
A12: 11 | B12: إدارة التشغيل | C12: stops.php | D12: التوقفات وتحديد المتحمل | E12: رابعًا: تسجيل عمل اليوم | F12: التوقفات | G12: 32 | H12: نعم | I12: 2 | J12: 4 | K12: 3 | L12: مطلوبة | M12: الفصلُ ٢ — سجلُّ الشاشات
A13: 12 | B13: إدارة التشغيل | C13: risk_dept_ops.php | D13: المخاطر التشغيلية | E13: مخاطرُ الإدارة | F13: مخاطرُ إدارتي | G13: 22 | H13: نعم | I13: 3 | J13: 1 | K13: 1 | L13: مطلوبة | M13: الفصلُ ٢ — سجلُّ الشاشات
... A256: 255 | B256: مساحة عملي | C256: my_tasks.php | D256: مهامي | E256: لوحة الإدارة التنفيذية | F256: مساحتي الشخصية | G256: 15 | H256: لا | I256: 1 | J256: 15 | K256: 0 | L256: غيرُ لازمة | M256: الفصلُ ٢ — سجلُّ الشاشات

Sheet 07 — سجل الأفعال والتدقيق
A1: # | B1: الرمزُ الحالي | C1: الاسمُ المقترحُ domain.resource.action | D1: الفعل | E1: الإدارة | F1: الشاشة | G1: الفاعل | H1: ما يُكتب | I1: الحدث | J1: المستهلك | K1: الأثر | L1: العكس | M1: ①معنًى | N1: ②alias | O1: ③مالك | P1: ④مصدر | Q1: ⑤معالج | R1: ⑥عكسٌ ماليّ | S1: ⑦دائرية | T1: ⑧الكود | U1: حاجب | V1: حالةُ الربط
A2: 1 | B2: ticket.open | C2: tickets.ticket.create | D2: فتحُ بلاغ | E2: مركز البلاغات | F2: أبلغ عن مشكلة من هذه الشاشة | G2: المستخدم | H2: tickets · ticket_context | I2: TicketOpened | J2: مركزُ البلاغات · الإدارةُ المختصة | K2: تذكرةٌ مصنَّفةٌ موجَّهةٌ آليًّا · ومهلةٌ تبدأ · وسياقُ الشاشة محفوظ | L2: إغلاقٌ إداريٌّ بمرجع | M2: ✔ | N2: ✔ | O2: ✔ | P2: ✔ | Q2: ◐ معلَّقُ الربطِ معلَنٌ | R2: ✔ | S2: ✔ | T2: ◐ يحتاج مقارنةً بالكود الحيّ | U2: لا | V2: معلَّقُ الربطِ — 228 من 242
A3: 2 | B3: ticket.ack | C3: tickets.ticket.receive | D3: استلامُ البلاغ | E3: مركز البلاغات | F3: بلاغات إدارتي | G3: المكلَّف | H3: tickets.state · sla | I3: TicketAcknowledged | J3: مركزُ البلاغات | K3: مهلةُ الاستجابة تتوقف · ومهلةُ الإنجاز تبدأ · والمكلَّفُ مسؤولٌ باسمه | L3: إعادةُ توجيهٍ بسبب | M3: ✔ | N3: ✔ | O3: ✔ | P3: ✔ | Q3: ◐ معلَّقُ الربطِ معلَنٌ | R3: ✔ | S3: ✔ | T3: ◐ يحتاج مقارنةً بالكود الحيّ | U3: لا | V3: معلَّقُ الربطِ — 228 من 242
A4: 3 | B4: ticket.done | C4: tickets.ticket.execute_done | D4: إنجازُ البلاغ | E4: مركز البلاغات | F4: بلاغات إدارتي | G4: المكلَّف | H4: tickets.state · resolution | I4: TicketResolved | J4: المبلِّغُ · المركز | K4: ينتظر تأكيدَ المبلِّغ — ولا يُغلق المكلَّفُ بنفسه | L4: إعادةُ فتحٍ بعدّاد | M4: ✔ | N4: ✔ | O4: ✔ | P4: ✔ | Q4: ◐ معلَّقُ الربطِ معلَنٌ | R4: ✔ | S4: ✔ | T4: ◐ يحتاج مقارنةً بالكود الحيّ | U4: لا | V4: معلَّقُ الربطِ — 228 من 242
A5: 4 | B5: approval.grant | C5: governance.approval.approve | D5: اعتمادٌ في سقفي | E5: الحوكمة والالتزام | F5: صندوق ما ينتظر اعتمادي | G5: المعتمِد | H5: approvals · audit | I5: ApprovalGranted | J5: الحلقةُ التالية | K5: المستندُ ينتقل · والتوقيعُ يُسجَّل بمرجع التفويض | L5: سحبٌ بقرارٍ موثَّق | M5: ✔ | N5: ✔ | O5: ✔ | P5: ✔ | Q5: ◐ معلَّقُ الربطِ معلَنٌ | R5: ✔ | S5: ✔ | T5: ◐ يحتاج مقارنةً بالكود الحيّ | U5: لا | V5: معلَّقُ الربطِ — 228 من 242
A6: 5 | B6: approval.reject | C6: governance.approval.execute_reject | D6: رفضٌ بسببٍ محكوم | E6: الحوكمة والالتزام | F6: صندوق ما ينتظر اعتمادي | G6: المعتمِد | H6: approvals · reasons | I6: ApprovalRejected | J6: المُنشئ · المسار | K6: المستندُ يعود لمُنشئه بسببٍ من قائمةٍ محكومة — ويُقاس السببُ في تحليل الاختناقات | L6: إعادةُ رفعٍ بعد التصحيح | M6: ✔ | N6: ✔ | O6: ✔ | P6: ✔ | Q6: ◐ معلَّقُ الربطِ معلَنٌ | R6: ✔ | S6: ✔ | T6: ◐ يحتاج مقارنةً بالكود الحيّ | U6: لا | V6: معلَّقُ الربطِ — 228 من 242
A7: 6 | B7: approval.return | C7: governance.approval.execute_return | D7: إعادةٌ للتصحيح | E7: الحوكمة والالتزام | F7: صندوق ما ينتظر اعتمادي | G7: المعتمِد | H7: approvals | I7: ApprovalReturned | J7: المُنشئ | K7: المستندُ يعود قابلًا للتعديل · والمهلةُ تتوقف حتى إعادة الرفع | L7: ◆ بلا عكس | M7: ✔ | N7: ✔ | O7: ✔ | P7: ✔ | Q7: ◐ معلَّقُ الربطِ معلَنٌ | R7: ✔ | S7: ✔ | T7: ◐ يحتاج مقارنةً بالكود الحيّ | U7: لا | V7: معلَّقُ الربطِ — 228 من 242
A8: 7 | B8: ach.range | C8: workspace.achievement.execute | D8: اختيارُ مدى الإنجاز | E8: مساحة عملي | F8: إنجازي | G8: المستخدم | H8: — | I8: — | J8: — | K8: يُعاد الحسابُ للمدى: يومًا أو أسبوعًا أو شهرًا أو سنةً أو بتاريخين | L8: ◆ بلا عكس | M8: ✔ | N8: ✔ | O8: ✔ | P8: ✔ | Q8: ◐ معلَّقُ الربطِ معلَنٌ | R8: ✔ | S8: ✔ | T8: ◐ يحتاج مقارنةً بالكود الحيّ | U8: لا | V8: معلَّقُ الربطِ — 228 من 242
A9: 8 | B9: plan.submit | C9: site.plan.submit | D9: رفعُ خطة الغد | E9: إدارة الموقع | F9: خطة عمل الغد | G9: مديرُ الموقع | H9: daily_plans · resource_locks | I9: PlanSubmitted | J9: التشغيل · القوى · الأسطول | K9: الحارسُ يفحص التأهيلَ والجاهزيةَ والوثائق · والمواردُ تُحجز مبدئيًّا | L9: سحبٌ قبل الاعتماد | M9: ✔ | N9: ✔ | O9: ✔ | P9: ✔ | Q9: ◐ معلَّقُ الربطِ معلَنٌ | R9: ✔ | S9: ✔ | T9: ◐ يحتاج مقارنةً بالكود الحيّ | U9: لا | V9: معلَّقُ الربطِ — 228 من 242
A10: 9 | B10: plan.approve | C10: site.plan.approve | D10: اعتمادُ خطة الموقع | E10: إدارة الموقع | F10: خطة عمل الغد | G10: مديرُ التشغيل | H10: daily_plans.state | I10: PlanApproved | J10: الموقع · القوى · الأسطول · النقل | K10: الخطةُ تصير نافذةً · ويُفتح التايم شيت عليها · وتُطلب رحلاتُ الترحيل الناقصة | L10: إعادةٌ بسببٍ محكوم | M10: ✔ | N10: ✔ | O10: ✔ | P10: ✔ | Q10: ◐ معلَّقُ الربطِ معلَنٌ | R10: ✔ | S10: ✔ | T10: ◐ يحتاج مقارنةً بالكود الحيّ | U10: لا | V10: معلَّقُ الربطِ — 228 من 242
A11: 10 | B11: plan.copy | C11: site.plan.execute | D11: نسخُ خطة الأمس | E11: إدارة الموقع | F11: خطة عمل الغد | G11: مديرُ الموقع | H11: daily_plans | I11: PlanDrafted | J11: الموقعُ وحدَه | K11: مسودةٌ بالتوزيع نفسِه — والحارسُ يعيد فحصَ الجاهزية والتأهيل قبل الرفع | L11: حذفُ المسودة | M11: ✔ | N11: ✔ | O11: ✔ | P11: ✔ | Q11: ◐ معلَّقُ الربطِ معلَنٌ | R11: ✔ | S11: ✔ | T11: ◐ يحتاج مقارنةً بالكود الحيّ | U11: لا | V11: معلَّقُ الربطِ — 228 من 242
A12: 11 | B12: asset.assign | C12: ops.asset.assign | D12: تخصيصُ معدةٍ لموقع | E12: إدارة التشغيل | F12: توزيع المعدات والمشغّلين | G12: مديرُ التشغيل | H12: assignments · equipment.location | I12: EquipmentAssigned | J12: الموقع · القوى · النقل · الأسطول | K12: المعدةُ تظهر في لوحة الموقع · وتُطلب رحلةُ ترحيلٍ إن اختلف الموقع · وتُطلب موافقةُ القوى | L12: إنهاءُ تخصيصٍ بتاريخٍ وسبب | M12: ✔ | N12: ✔ | O12: ✔ | P12: ✔ | Q12: ◐ معلَّقُ الربطِ معلَنٌ | R12: ✔ | S12: ✔ | T12: ◐ يحتاج مقارنةً بالكود الحيّ | U12: لا | V12: معلَّقُ الربطِ — 228 من 242
A13: 12 | B13: operator.swap | C13: ops.operator.execute | D13: تبديلُ مشغّلٍ على معدة | E13: إدارة التشغيل | F13: توزيع المعدات والمشغّلين | G13: مديرُ التشغيل | H13: operator_assignments · approvals | I13: OperatorSwapRequested | J13: القوى · الموارد · الموقع | K13: لا يقع التبديلُ قبل موافقة القوى · وبعدها يتغير التايم شيت والاستحقاق والحافز | L13: إلغاءُ الطلب أو عكسُ التبديل | M13: ✔ | N13: ✔ | O13: ✔ | P13: ✔ | Q13: ◐ معلَّقُ الربطِ معلَنٌ | R13: ✔ | S13: ✔ | T13: ◐ يحتاج مقارنةً بالكود الحيّ | U13: لا | V13: معلَّقُ الربطِ — 228 من 242
... A363: 362 | B363: risk.settings.review | C363: core.risk.define_settings | D363: ضبطُ دوريةِ المراجعةِ بحسب الدرجة | E363: RSK | F363: إعدادات المخاطر والتصنيف | G363: مديرُ المخاطر | H363: risk_settings | I363: RiskReviewCycleSet | J363: المخاطرُ والإداراتُ المالكة | K363: الحرجُ شهريًّا والمرتفعُ ربعَ سنويٍّ والمتوسطُ نصفَ سنويٍّ والمنخفضُ سنويًّا | L363: إعادةُ الدوريةِ السابقة | M363: ✔ | N363: ✘ معنًى بعدةِ رموزٍ بلا alias | O363: ✘ بلا مالك | P363: ✔ | Q363: ◐ معلَّقُ الربطِ معلَنٌ | R363: ✔ | S363: ✔ | T363: ◐ يحتاج مقارنةً بالكود الحيّ | U363: نعم | V363: معلَّقُ الربطِ — 228 من 242

Sheet 08 — خطة ترحيل الرموز
A1: # | B1: الخطوة | C1: ما يُفعل | D1: الشاهد | E1: لا يُنتقل قبلها | F1: الحالة
A2: 1 | B2: مصفوفةُ استعمال | C2: حصرُ كلِّ موضعٍ يقرأ الرمزَ أو يكتبه: الكودُ والقاموسُ والتقاريرُ وAPI | D2: جدولٌ بالرمزِ وعددِ مواضعه ومساراتها | E2: Dry Run | F2: لم تبدأ — تحتاج الكودَ الحيّ
A3: 2 | B3: Dry Run | C3: تشغيلُ الترحيلِ على نسخةٍ بلا كتابةٍ وقياسُ الفرق | D3: تقريرُ فرقٍ يبيّن كلَّ تغييرٍ متوقَّع | E3: خريطةِ alias | F3: لم تبدأ
A4: 3 | B4: خريطةُ alias | C4: الرمزُ القديمُ يبقى alias للجديدِ دورةَ إصدارٍ كاملة | D4: جدولُ قديمٍ ← جديدٍ بتاريخِ الهجران | E4: اختبارِ الرجوع | F4: لم تبدأ
A5: 4 | B5: اختبارُ الرجوع | C5: إثباتُ إمكانيةِ العودةِ للرموز القديمةِ بلا فقدِ بيانات | D5: تقريرُ رجوعٍ ناجحٍ في بيئةِ ما قبل الإنتاج | E5: اعتمادِ التنفيذ | F5: لم تبدأ
A6: 5 | B6: اعتمادُ التنفيذ | C6: توقيعُ المالكِ على الترحيلِ بعد الشواهد الأربعة | D6: اعتمادٌ موثَّقٌ بتاريخه | E6: التنفيذ | F6: لم تبدأ
A7: 6 | B7: التنفيذُ التدريجي | C7: ترحيلٌ بدفعاتٍ — تبدأ بالرموز الأربعةِ الحاجبة | D7: صفرُ كسرٍ بعد كل دفعة | E7: — | F7: لم تبدأ
A8: ◆ | B8: الحكم | C8: لا يُغيَّر رمزٌ في الكودِ مباشرةً — والأربعةُ الحاجبةُ تُصلَح في الوثيقةِ والقاموسِ أولًا ثم في الكودِ بالخطوات الستّ | D8: — | E8: — | F8: —

Sheet 09 — سجل العيوب المفتوحة
A1: معرّفٌ ثابت | B1: الوصف | C1: الخطورة | D1: الطبقةُ المتأثرة | E1: المالك | F1: سببُ المشكلة | G1: الأثر | H1: أيمنع الإطلاق | I1: القرارُ المطلوب | J1: المهلة | K1: دليلُ الإصلاح | L1: اختبارُ الإغلاق | M1: تاريخُ الإغلاق | N1: من راجع
A2: DEF-001 | B2: أربعةُ رموزِ أفعالٍ تحمل معنيين — model.define و req.raise | C2: حرجة | D2: قاموسُ الأفعالِ والكود | E2: مكتبُ الهندسة | F2: الرمزُ القصيرُ بلا نطاقٍ يتصادم | G2: حملةُ ربطِ الـ228 ستربط معنيين بمعالجٍ واحد | H2: نعم | I2: أيُعتمد نمطُ domain.resource.action للكلِّ أم للحاجبةِ وحدَها؟ | J2: قبل حملةِ الربط | K2: الورقةُ 07 تُظهر صفرَ رمزٍ لأكثرَ من معنى | L2: التدقيقُ العالميُّ يعيد صفرًا في الفحص الأول
A3: DEF-002 | B3: نواةُ التأجيرِ تُبنى خارجَ المعماريةِ الموثَّقة | C3: حرجة | D3: المعماريةُ ونظامُ الشاشات | E3: الرئيسُ التنفيذي | F3: جلسةٌ موازيةٌ بنت ثلاثَ شاشاتٍ خارج NAV-09 | G3: يكسر PR-01 مصدرَ الحقيقةِ الواحد · ولا نموذجَ رابعًا في E-09 | H3: نعم | I3: أتُوثَّق نواةُ التأجيرِ في الحزمةِ أم تُعلَن خارجَ النطاق؟ | J3: عاجل | K3: NAV-09 v5 يضمُّ شاشاتِها بمراحلها وأحكامها | L3: صفرُ رابطٍ خارجَ الوثيقةِ في فاحص nav09_verify
A4: DEF-003 | B4: 228 فعلًا من 242 معلَّقُ الربطِ بمعالجه الحي | C4: عالية | D4: طبقةُ الأفعال | E4: مكتبُ الهندسة | F4: القاموسُ استُورد كاملًا والربطُ في أوله | G4: الأثرُ لا يُتتبَّع من الزرِّ إلى القيد | H4: لا | I4: لا يحتاج قرارًا — يحتاج حملةً بعد DEF-001 | J4: بعد DEF-001 | K4: nav09_action_map: live_code لكل رمز | L4: صفرُ رمزٍ بحالة pending
A5: DEF-004 | B5: 67 وجهةً بلا وحدةِ صلاحياتٍ مسجَّلة من 203 | C5: عالية | D5: الصلاحياتُ والحوكمة | E5: الحوكمةُ والالتزام | F5: الشاشاتُ محميةٌ بحارسها وأرضيةِ الحوكمةِ بلا وحدةٍ مسجَّلة | G5: تُحرَم من صفوف can_view/can_edit ومن شاشة الصلاحيات | H5: لا | I5: لا يحتاج قرارًا — تسجيلٌ إجرائي | J5: قبل الإطلاق | K5: modules: 203/203 | L5: صفرُ وجهةٍ بلا وحدة
A6: DEF-005 | B6: فاحصُ الحوكمةِ يغطي 194 شاشةً من 203 | C6: متوسطة | D6: الحوكمةُ والالتزام | E6: الحوكمةُ والالتزام | F6: تسعُ شاشاتٍ خارجَ نطاق الفاحصِ بلا سببٍ معلَن | G6: مخالفةُ أعمدةٍ حاكمةٍ قد تمرُّ غيرَ مكتشفة | H6: لا | I6: أالتسعُ مستثناةٌ بقصدٍ أم سقطت؟ | J6: قبل الإطلاق | K6: cmp03_gov_check: 203/203 أو استثناءٌ معلَن | L6: الفاحصُ يعلن نطاقَه صريحًا
A7: DEF-006 | B7: عدّادا تبنّي E-03 على 286 والشاشاتُ القانونيةُ 203 | C7: متوسطة | D7: نظامُ الشاشات | E7: مكتبُ الهندسة | F7: مقامٌ مختلفٌ بلا تعريفٍ معلَن | G7: النسبُ غيرُ قابلةٍ للمقارنةِ بأرقام NAV-09 | H7: لا | I7: ما تعريفُ الـ286؟ أهي 203 + التأجيرُ + غيرُها؟ | J7: قبل التقرير القادم | K7: تعريفٌ معلَنٌ للمقامِ في كل عدّاد | L7: كلُّ نسبةٍ تذكر مقامَها ومصدرَه
A8: DEF-007 | B8: «الحالاتُ الخمسُ» بُنيت مركزيًّا — والنموذجُ المعتمدُ خمسةُ محاور | C8: عالية | D8: النظامُ التصميميُّ والشاشات | E8: مكتبُ الهندسة | F8: قائمةٌ واحدةٌ تخلط محاورَ مختلفةً بدل تركيبها | G8: الشاشةُ ببياناتٍ وقراءةٍ فقط ودون اتصالٍ لا تُمثَّل بحالةٍ واحدة | H8: لا | I8: أتُعاد النمذجةُ إلى المحاور الخمسةِ بـCM-00؟ | J8: قبل تعميقِ التبنّي | K8: CM-00 مبنيٌّ ويركّب المحاورَ الخمسة | L8: اختبارُ تركيبةِ «بياناتٌ + قراءةٌ فقط + دون اتصال»
A9: DEF-008 | B9: ورقةُ الزائدِ 1261 صفًّا والمصنَّفُ 870 | C9: عالية | D9: قاموسُ البياناتِ والأعمدة | E9: مكتبُ الهندسة | F9: نسخةُ الفريقِ أحدثُ من نسخةِ التصنيف | G9: 391 صفًّا بلا حكم | H9: لا | I9: لا يحتاج قرارًا — يحتاج ورقةَ مصالحة | J9: عاجل | K9: DEC-SCR-01 يُعاد تشغيلُه على 1261 | L9: صفرُ صفٍّ بلا حكمٍ من التسعة
A10: DEF-009 | B10: 65 جدولًا قديمًا بلا عمود كيان | C10: عالية | D10: العزلُ وتعددُ الشركات | E10: مكتبُ الهندسة | F10: جداولُ سابقةٌ لمبدأ العزل | G10: يخالف PR-02 — واستعلامٌ قد يتجاوز الكيان | H10: نعم | I10: أُقِرَّ: فاحصٌ يبلّغ لا هجرة — أيُرفع إلى هجرةٍ قبل الإطلاق؟ | J10: قبل GA | K10: كلُّ جدولٍ يحمل عمودَ الكيانِ أو استثناءً معلَنًا | L10: اختبارُ تسربٍ يفشل في كل المسارات
A11: DEF-010 | B11: 5,986 تصادمًا تاريخيًّا يمنع قيدَ UNIQUE | C11: عالية | D11: دورةُ الوحدةِ والتايم شيت | E11: الرئيسُ التنفيذي | F11: بياناتٌ تاريخيةٌ بمعدةٍ وتاريخٍ ووردية مكررة | G11: لا يمكن فرضُ التفردِ بلا معالجةِ القائم | H11: نعم | I11: أتُدمج التصادماتُ أم تُوسَم استثناءً تاريخيًّا؟ | J11: قبل GA | K11: قيدُ UNIQUE مفعَّلٌ وصفرُ تصادمٍ جديد | L11: محاولةُ إدخالٍ مكررٍ تُرفض
A12: DEF-011 | B12: مخالفتا أعمدةِ حوكمةٍ في المشتريات | C12: متوسطة | D12: الحوكمةُ والالتزام | E12: المشتريات | F12: تعديلاتُ اليومِ أسقطت أعمدةً حاكمة | G12: wh_receipt تنقصها ستةٌ و po_match عمودان | H12: لا | I12: لا يحتاج قرارًا — استدراكٌ قبل الالتزام | J12: فوري | K12: cmp03_gov_check: 194/194 | L12: صفرُ شاشةٍ بعمودٍ حاكمٍ ناقص
A13: DEF-013 | B13: ثلاثُ إداراتٍ مركزيةٍ ناقصةٌ من الهيكل: المخاطرُ والمشترياتُ المركزيةُ وشؤونُ العاملين بالمشروعات | C13: عالية | D13: الهيكلُ التنظيميُّ والحزمة | E13: الرئيسُ التنفيذي | F13: بُني الهيكلُ على سبعَ عشرةَ إدارةً ولم تُحسم الثلاث | G13: لا وثيقةَ لها ولا شاشاتَ ولا صلاحياتٍ ولا فصلَ في FRD | H13: نعم | I13: أتُعتمد الثلاثُ إداراتٍ مستقلةً؟ وما اختصاصُ كلٍّ وحدُّها مع القائم؟ | J13: عاجل | K13: الورقةُ 05 تحمل الثلاثَ بحالةِ «نافذ» وفصلٍ في FRD | L13: صفرُ إدارةٍ بحالة «◆ ناقص» في الورقة 05
A14: DEF-014 | B14: علاقةُ مديرِ الموقعِ كانت خاطئةً في الهيكلِ المنشور | C14: حرجة | D14: الهيكلُ والصلاحياتُ والموافقات | E14: مكتبُ الهندسة | F14: عُدَّت إدارةُ الموقعِ تابعةً للإداراتِ التشغيليةِ الخمس | G14: مديرُ الموقعِ تحت خمسةِ رؤساءَ · وparent_org_unit ومساراتُ الموافقةِ والصلاحياتُ والسايدبار مبنيةٌ على علاقةٍ خاطئة | H14: نعم | I14: لا يحتاج قرارًا — صُحِّح: الفرعان متوازيان تحت مدير التشغيل | J14: منفَّذٌ في هذه الجولة | K14: الورقةُ 12 تُظهر الفرعين متوازيين | L14: parent_org_unit لمديرِ الموقعِ = مديرُ التشغيلِ وحدَه | M14: 2026-08-06 | N14: مكتبُ الهندسة
A15: DEF-015 | B15: أرقامٌ أُعلنت بلا حساب — توزيعُ الأحكامِ على الوجهات | C15: متوسطة | D15: التقاريرُ والإعلان | E15: مكتبُ الهندسة | F15: أُعلنت تقديراتٌ (≈2,850 و≈1,900 و≈750) مجموعُها 5,548 والواقعُ 3,815 | G15: تناقضٌ ظاهرٌ يُفقد الثقةَ في بقيةِ الأرقام | H15: لا | I15: لا يحتاج قرارًا — قاعدةٌ منهجية: لا يُعلَن رقمٌ لم يُحسب من الملف | J15: منفَّذٌ في هذه الجولة | K15: لوحةُ الاتساقِ تحسب كلَّ رقمٍ بصيغةٍ من الورقة نفسِها | L15: صفرُ رقمٍ تقديريٍّ في أي تقرير | M15: 2026-08-06 | N15: مكتبُ الهندسة
A16: DEF-016 | B16: ثلاثةُ أعمدةٍ في SCR-DES-01 تحمل المسمّى القياديَّ القديم «الإدارة العامة» | C16: منخفضة | D16: تصميمُ الأعمدةِ والشاشات | E16: مكتبُ الهندسة | F16: أُنشئت قبل اعتماد نموذجِ الرئيسِ والنواب | G16: تظهر في M-10 و M-13 — وتُربك القارئَ الخارجيَّ ولا تُفسد وظيفة | H16: لا | I16: لا يحتاج قرارًا — تصحيحٌ في SCR-DES-01 عبر مسار التغييرِ الرسميّ | J16: قبل العرض الخارجي | K16: ◆ لا تُصحَّح من مولّد الوثائق — فالملفُّ حيٌّ ومصدرُ تحققٍ حاكم | L16: صفرُ عمودٍ يحمل المسمّى القديمَ في SCR-DES-01 v2
A17: DEF-012 | B17: NAV-09 يحتاج نسخةً خامسةً تضمُّ التأجير | C17: عالية | D17: نظامُ الشاشات | E17: مكتبُ الهندسة | F17: شاشاتٌ حيةٌ خارجَ الوثيقة | G17: «التوليدُ من الوثيقة» يفقد صدقَه | H17: نعم | I17: مرتبطٌ بـDEF-002 — بعد قرارِ التوثيق | J17: بعد DEF-002 | K17: NAV-09 v5 ببصمةٍ جديدةٍ في الورقة 01 | L17: فاحصُ nav09_verify صفرُ مخالفة

Sheet 10 — القرارات وحالة الحسم
A1: الرمز | B1: الموضوع | C1: حالةُ الحسم | D1: الحكمُ النافذُ الآن | E1: السببُ المهني | F1: ما يبقى للمالك
A2: ◆ القراراتُ الحرجةُ الأربعة
A3: CR-01 | B3: نمذجةُ حالاتِ الشاشةِ — bootFiveStates | C3: ◆ محسومٌ تقنيًّا الآن — ولا يحتاج قرارَ مالك | D3: الحكم: تُعاد النمذجةُ إلى خمسةِ محاورَ مستقلةٍ يركّبها الغلافُ الحاكمُ CM-00 — ولا تُبنى قائمةً واحدة · لماذا: «تحميل · فارغة · خطأ» محورٌ واحد · و«دون اتصال» محورٌ آخر · و«نجاح» ليست حالةَ شاشةٍ بل تغذيةً راجعةً لحظية · والغائبُ: لا نتائجَ للبحثِ وبلا صلاحيةٍ وقراءةٌ فقط والبياناتُ القديمة · الحالةُ الواقعية: الشاشةُ الميدانيةُ تكون «ببياناتٍ + قراءةٌ فقط + دون اتصال + بياناتٌ من قبل ثلاثِ ساعات» في آنٍ واحد — ولا تُمثَّل بحالةٍ واحدة · ◆ الصياغةُ الدقيقة: لا يُقال «العيبُ مزروعٌ في 288 شاشة» — فـv13 تثبت مركزيةَ النموذجِ ولا تثبت تبنّيَه في كلٍّ. والصحيح: النموذجُ المركزيُّ يحتاج تصحيحًا · وكلُّ شاشةٍ تتبناه تحمل العيبَ · ويُقاس التبنّي الفعليُّ أولًا · ما يُنفَّذ الآن: يوقف تعميقُ bootFiveStates · ويُبنى CM-00 بثمانِ خطواتٍ · ويُقاس التبنّي الفعليُّ · ثم تُهاجَر الشاشاتُ بدفعاتٍ من عشرين · الأثرُ إن تأخر: كلُّ شاشةٍ جديدةٍ تتبنى النموذجَ الخطأ — والتصحيحُ يتضاعف بعددها | E3: — | F3: —
A4: CR-02 | B4: تعريفُ المقاييسِ — 249 و288 و203 و1,075 | C4: ◆ محسومٌ تقنيًّا الآن — قاموسُ مقاييسٍ لا توحيدٌ قسري | D4: الحكم: تُعرَّف المقاييسُ الأربعةُ صريحةً في قاموسٍ داخلَ المعمارية — ولا تُوحَّد قسرًا · Legal Screen شاشةٌ قانونيةٌ فريدةٌ في NAV-09 — المصدر: NAV-09 · العدد: 203 · Registered Screen سجلُّ شاشةٍ في جدول modules — المصدر: القاعدةُ الحية · العدد: 249 · UX Adoption Unit وحدةٌ يُطبَّق عليها معيارُ E-03 — المصدر: عدّادُ التبنّي · العدد: 288 · Navigation Item ظهورٌ فعليٌّ لدورٍ ونطاق — المصدر: nav_items · العدد: 1,075 · الحكمُ الملزم: ◆ كلُّ نسبةٍ تُعلَن تذكر مقامَها ومصدرَه — ولا نسبةَ بلا مقامٍ معرَّف | E4: — | F4: —
A5: CR-03 | B5: نواةُ التأجيرِ وقاعدةُ NAV-09 | C5: ◆ القاعدةُ محسومةٌ الآن — والقرارُ التجاريُّ للمالك | D5: ◆ القاعدةُ الحاكمة: Build ahead — never release ahead · يُبنى قبل التوثيقِ ولا يُصدَر قبله · ما يجوز: بناءُ شاشةٍ جديدةٍ في فرع تطويرٍ أو بيئةِ اختبارٍ قبل تحديث NAV-09 · ما لا يجوز: دخولُها إصدارًا · ظهورُها في الإنتاج · صيرورتُها جزءًا من السايدبار النافذ · الشروطُ الخمسةُ للإفراج: تُضاف إلى NAV-09 · تُحدَّد مرحلتُها ومالكُها ونطاقُها · تُبصَم النسخةُ · يُعاد توليدُ التنقلِ منها · يجتاز فحصَ المطابقة · أثرُها على ق-16: يبقى «الأحدثُ يغلب» نافذًا في المضمون — ويُقيَّد بألّا يتحول الرابطُ الجديدُ مصدرًا ثانيًا للتنقل · ◆ ما يبقى للمالك: أتُوثَّق نواةُ التأجيرِ نموذجًا رابعًا في E-09 أم تُعلَن خارجَ النطاقِ بقرار؟ — والقاعدةُ أعلاه تحكمها في الحالين | E5: — | F5: —
A6: CR-04 | B6: طوبولوجيا القاعدتين 3306 و3307 | C6: ◆ خطرٌ حاكمٌ — يحتاج بيانًا من الفريقِ وقرارَ المالك | D6: الخطر: التشغيلُ المزدوجُ إن كانت القاعدتان قابلتين للكتابةِ معًا يُنتج انقسامَ العقل Split Brain — وهو أخطرُ من فجوةِ الواجهةِ كلِّها · الأسئلةُ الثمانيةُ التي يجب أن يجيبها قسمٌ جديد: أيُّ قاعدةٍ مصدرُ الحقيقة؟ · أ3306 للقراءةِ فقط أم قابلةٌ للكتابة؟ · أتوجد مزامنةٌ وما اتجاهُها؟ · ما سلوكُ التعارض؟ · ما خطةُ القلب؟ · متى تُطفأ القديمة؟ · كيف نرجع إن فشل الانتقال؟ · من يملك القرار؟ · الحكمُ المؤقتُ الآمن: حتى يصدر البيانُ — تُعامَل 3306 قاعدةً موروثةً للقراءةِ فقط · ولا كتابةَ فيها · ويُوثَّق أيُّ استثناءٍ صريحًا · ◆ إن كانت الاثنتان قابلتين للكتابةِ فعلًا: فهذا عيبٌ حرجٌ يمنع الإطلاقَ ويُرفع فورًا — لا دَينٌ يُؤجَّل | E6: — | F6: —
A7: ◆ القراراتُ التسعة
A8: DEC-A | B8: نمطُ تسميةِ الأفعال | C8: ◆ محسومٌ تقنيًّا | D8: domain.resource.action لكل الرموزِ الـ242 — بمميِّزٍ عند التصادمِ وترحيلٍ بمرادفاتٍ دورةَ إصدارٍ كاملة | E8: النمطُ الجزئيُّ يُنتج قاموسًا مختلطًا يصعب صيانتُه · والمرادفُ يمنع الكسرَ أثناء الترحيل | F8: أربعةُ صفوفٍ برمزين يحملان معنيين تُصلَح أولًا قبل حملةِ الربط
A9: DEC-B | B9: نواةُ التأجير | C9: ◆ القاعدةُ محسومةٌ · والقرارُ التجاريُّ للمالك | D9: Build ahead — never release ahead · وأيًّا كان قرارُ التوثيقِ فالقاعدةُ تحكم | E9: تفصل بين سرعةِ التطويرِ ووحدةِ مصدرِ الحقيقةِ بلا كسرِ أحدهما | F9: يبقى سؤالُ المالك: نموذجٌ رابعٌ في E-09 أم خارجُ النطاق؟
A10: DEC-C | B10: التصادماتُ التاريخيةُ 5,986 | C10: ✔ حُسم — قرارُ مالكٍ نافذ | D10: الموروثُ معلَنٌ خارجَ الدرعِ · والدرعُ يعمل على السكةِ الجديدةِ بقادحين | E10: مطابقٌ للتوصيةِ المهنيةِ — فالدمجُ الآليُّ يفقد بياناتٍ واليدويُّ يستحيل في 5,986 | F10: ◆ مغلقٌ — ق-18
A11: DEC-D | B11: الـ65 جدولًا بلا عمود كيان | C11: ◆ المنهجُ محسومٌ — والتصنيفُ يحتاج القاعدةَ الحية | D11: لا يُفرَض company_id على الكلِّ — بل يُصنَّف كلُّ جدولٍ في أحد أربعةِ أصناف: Global · معزولٌ عبر الأبِ · موروثٌ محجورٌ · مستأجَرٌ يجب ترحيلُه | E11: ◆ الحكمُ المهني: إثباتُ مسارِ العزلِ لكلٍّ · فما كان آمنًا عبر أبيه أو عامًّا فلا مشكلةَ معماريةً فيه | F11: المستأجَرُ الحقيقيُّ بلا عزلٍ مباشرٍ ولا غيرِ مباشرٍ = دَينٌ أمنيٌّ يمنع الإطلاق
A12: DEC-E | B12: نمذجةُ حالاتِ الشاشة | C12: ◆ محسومٌ تقنيًّا | D12: خمسةُ محاورَ مستقلةٍ يركّبها CM-00 — ويوقف تعميقُ bootFiveStates | E12: القائمةُ الواحدةُ تخلط محاورَ وتُسقط أربعَ قيمٍ ضرورية | F12: يُقاس التبنّي الفعليُّ قبل تحديدِ عددِ الشاشات المتأثرة
A13: DEC-F | B13: تعريفُ المقاييس | C13: ◆ محسومٌ تقنيًّا | D13: قاموسُ مقاييسٍ بأربعةِ تعريفاتٍ داخلَ المعمارية — ولا توحيدَ قسريّ | E13: الأرقامُ ليست متناقضةً بل غيرَ معرَّفةٍ — والتعريفُ ينهي المشكلةَ نهائيًّا | F13: ◆ كلُّ نسبةٍ تذكر مقامَها ومصدرَه
A14: DEC-G | B14: إدارةُ المخاطر | C14: ◆ يبقى للمالك — والحكمُ المؤقتُ نافذ | D14: التوصية: إدارةٌ مركزيةٌ مستقلةٌ بوصولٍ مباشرٍ للرئيسِ في المخاطر الجوهرية | E14: المخاطرُ التي تُدار من داخل الحوكمةِ تفقد استقلالَها عن الجهةِ التي تراقبها | F14: الحكمُ المؤقت: تبقى «المخاطرُ التجارية» شاشةً في التنفيذيةِ ولا تُخترع لها دورةٌ ولا شاشات
A15: DEC-H | B15: المشترياتُ المركزية | C15: ◆ يبقى للمالك — والحكمُ المؤقتُ نافذ | D15: التوصية: إدارةٌ مركزيةٌ للشراءِ الاستراتيجيِّ والعقودِ الإطاريةِ وما فوقَ سقفِ التشغيلية | E15: الشراءُ الاستراتيجيُّ قرارٌ ماليٌّ لا تشغيليّ · والدمجُ يجعل التشغيليةَ تقرر ما يفوق سقفها | F15: الحكمُ المؤقت: كلُّ شراءٍ يمرُّ بالتشغيليةِ · وما فوقَ سقفِها يُرفع للنائبِ المالي
A16: DEC-I | B16: شؤونُ العاملين بالمشروعات | C16: ◆ يبقى للمالك — والحكمُ المؤقتُ نافذ | D16: التوصية: وحدةٌ مركزيةٌ تحت نائب الشؤون الإداريةِ والحوكمة | E16: العقودُ المشروعيةُ والتعبئةُ والتسريحُ التزامٌ وظيفيٌّ لا تشغيليّ · وإخضاعُها للتشغيلِ يخلط الأجرَ بالإنتاج | F16: الحكمُ المؤقت: تُدار من الموارد البشريةِ بوسمٍ «مشروعيّ» ولا وحدةَ مستقلةٌ بعد

Sheet 11 — لوحة الاتساق
A1: البند | B1: العدد | C1: المصدر | D1: الحكم
A2: ملفاتٌ مبصومةٌ في خط الأساس | B2: =COUNTA('01 — بيان التجميد وسجل الوثائق'!$A$2:$A$64) | C2: الورقةُ 01 | D2: كلُّها ببصمةٍ وحجمٍ وتاريخٍ وحالة
A3: ◆ ملفاتٌ حيةٌ تبقى مستقلة | B3: =COUNTIF('01 — بيان التجميد وسجل الوثائق'!$G$2:$G$64,"ملفٌّ حيّ*") | C3: الورقةُ 01 | D3: NAV-09 و SCR-DES-01 و CMP-03 — لا تُدمج
A4: وثائقُ أحكامٍ نافذةٌ تُدمج | B4: =COUNTIF('01 — بيان التجميد وسجل الوثائق'!$G$2:$G$64,"نافذة*") | C4: الورقةُ 01 | D4: تُقرأ ثم تُؤرشَف
A5: مراجعُ بياناتٍ تُنقل أوراقُها | B5: =COUNTIF('01 — بيان التجميد وسجل الوثائق'!$G$2:$G$64,"مرجع*") | C5: الورقةُ 01 | D5: إلى أوراق هذا الملف
A6: وثائقُ تاريخية | B6: =COUNTIF('01 — بيان التجميد وسجل الوثائق'!$G$2:$G$64,"تاريخية") | C6: الورقةُ 01 | D6: أرشيفٌ مرجعيٌّ غيرُ نافذ
A7: ◆ الأحكامُ المنقولة
A8: إجماليُّ الأحكام | B8: =COUNTA('03 — سجل الأحكام النهائية'!$A$2:$A$5531) | C8: الورقةُ 03 | D8: كلٌّ بمصدرِه وقسمِه ووجهتِه واختبارِه
A9: إلى INJAZ-CORE-01 | B9: =COUNTIF('03 — سجل الأحكام النهائية'!$H$2:$H$5531,"INJAZ-CORE-01") | C9: الورقةُ 03 | D9: الدستورُ والمعماريةُ والحوكمة
A10: إلى INJAZ-FRD-01 | B10: =COUNTIF('03 — سجل الأحكام النهائية'!$H$2:$H$5531,"INJAZ-FRD-01") | C10: الورقةُ 03 | D10: المتطلباتُ الوظيفيةُ بفصلٍ لكل إدارة
A11: إلى INJAZ-UX-01 | B11: =COUNTIF('03 — سجل الأحكام النهائية'!$H$2:$H$5531,"INJAZ-UX-01") | C11: الورقةُ 03 | D11: الشاشاتُ والتجربةُ والنظامُ التصميمي
A12: إلى INJAZ-DELIVERY-01 | B12: =COUNTIF('03 — سجل الأحكام النهائية'!$H$2:$H$5531,"INJAZ-DELIVERY-01") | C12: الورقةُ 03 | D12: التنفيذُ والتتبعُ والاختبار
A13: ◆ التدقيقُ العالميُّ للأفعال
A14: أفعالٌ مدقَّقة | B14: =COUNTA('07 — سجل الأفعال والتدقيق'!$A$2:$A$363) | C14: الورقةُ 07 | D14: بثمانيةِ فحوصٍ لكلٍّ
A15: حاجبةٌ للتجميع | B15: =COUNTIF('07 — سجل الأفعال والتدقيق'!$U$2:$U$363,"نعم") | C15: الورقةُ 07 | D15: ◆ تُصلَح قبل نقلِ القاموس
A16: رمزٌ لأكثرَ من معنى | B16: =COUNTIF('07 — سجل الأفعال والتدقيق'!$M$2:$M$363,"✘*") | C16: الورقةُ 07 | D16: الفحصُ الأول
A17: معنًى بعدةِ رموزٍ بلا alias | B17: =COUNTIF('07 — سجل الأفعال والتدقيق'!$N$2:$N$363,"✘*") | C17: الورقةُ 07 | D17: الفحصُ الثاني — صفرٌ بعد النمط
A18: ماليٌّ أو تعاقديٌّ بلا عكس | B18: =COUNTIF('07 — سجل الأفعال والتدقيق'!$R$2:$R$363,"✘*") | C18: الورقةُ 07 | D18: الفحصُ السادس
A19: معلَّقُ الربطِ بالمعالج | B19: =COUNTIF('07 — سجل الأفعال والتدقيق'!$Q$2:$Q$363,"◐*") | C19: الورقةُ 07 | D19: يحتاج الكودَ الحيّ
A20: ◆ الهيكلُ التنظيمي
A21: إداراتٌ ووحداتٌ في الهيكل | B21: =COUNTA('05 — الإدارات والدورات'!$C$2:$C$40)-1 | C21: الورقةُ 05 | D21: بأنواعِ عقدٍ سبعةٍ لا بجمعٍ أعمى
A22: منها مبنيٌّ في الحزمة | B22: 18 | C22: orgmodel2 | D22: له وثيقةٌ وشاشاتٌ وأحكام
A23: ◆ ناقصٌ يحتاج قرارَ المالك | B23: 2 | C23: orgmodel2 | D23: المخاطرُ والمشترياتُ المركزيةُ وشؤونُ العاملين
A24: أدوارٌ بتبعيةٍ مزدوجة | B24: 9 | C24: الورقةُ 13 | D24: التقاطعُ في الطبقة الخامسةِ — أدوارٌ لا إدارات
A25: ◆ تصادمُ رموز الأفعال
A26: رموزٌ متصادمةٌ مسجَّلة | B26: =COUNTA('14 — تصادم رموز الأفعال'!$A$2:$A$40)-1 | C26: الورقةُ 14 | D26: بنوعِ تصادمٍ وحالةٍ لكلٍّ
A27: MEANING_COLLISION حاجب | B27: =COUNTIF('14 — تصادم رموز الأفعال'!$D$2:$D$40,"MEANING*") | C27: الورقةُ 14 | D27: ◆ يُصلَح قبل نقل القاموس
A28: ALIAS محلول | B28: =COUNTIF('14 — تصادم رموز الأفعال'!$D$2:$D$40,"ALIAS*") | C28: الورقةُ 14 | D28: معنًى واحدٌ في شاشاتٍ عدة
A29: ◆ تصنيفُ الكتابةِ وطبيعةُ الشاشة
A30: Domain Write | B30: =COUNTIF('21 — تصنيف الكتابة للأفعال'!$F$2:$F$300,"Domain Write") | C30: الورقةُ ٢١ | D30: يغيّر بيانَ العملِ وينشر حدثًا
A31: Governance Write | B31: =COUNTIF('21 — تصنيف الكتابة للأفعال'!$F$2:$F$300,"Governance Write") | C31: الورقةُ ٢١ | D31: ◆ تصديرٌ يكتب سجلَّ حوكمةٍ لا بيانَ مجال
A32: Read Only | B32: =COUNTIF('21 — تصنيف الكتابة للأفعال'!$F$2:$F$300,"Read Only") | C32: الورقةُ ٢١ | D32: لا يكتب ولا ينشر
A33: External Side Effect | B33: =COUNTIF('21 — تصنيف الكتابة للأفعال'!$F$2:$F$300,"External Side Effect") | C33: الورقةُ ٢١ | D33: إرسالٌ خارجَ النظام
A34: شاشاتٌ مستندٌ يُعتمد | B34: =COUNTIF('22 — طبيعة الشاشة'!$E$2:$E$300,"مستندٌ يُعتمد") | C34: الورقةُ ٢٢ | D34: تلزمها الأعمدةُ السبعةُ كاملةً
A35: شاشاتٌ سجلٌّ أو إعداد | B35: =COUNTIF('22 — طبيعة الشاشة'!$E$2:$E$300,"سجلٌّ أو إعداد") | C35: الورقةُ ٢٢ | D35: تلزمها أربعةٌ
A36: شاشاتٌ قارئة | B36: =COUNTIF('22 — طبيعة الشاشة'!$E$2:$E$300,"قارئة") | C36: الورقةُ ٢٢ | D36: يلزمها الكيانُ وحدَه
A37: ◆ تحتاج مراجعةً بشرية | B37: =COUNTIF('22 — طبيعة الشاشة'!$J$2:$J$300,"◆*") | C37: الورقةُ ٢٢ | D37: لم يحسمها الفعلُ ولا الاسم
A38: ◆ العيوبُ المفتوحة
A39: عيوبٌ مسجَّلة | B39: =COUNTA('09 — سجل العيوب المفتوحة'!$A$2:$A$17) | C39: الورقةُ 09 | D39: سجلٌّ حيٌّ يبدأ بها ولا يقتصر عليها
A40: حرجة | B40: =COUNTIF('09 — سجل العيوب المفتوحة'!$C$2:$C$17,"حرجة") | C40: الورقةُ 09 | D40: تمنع الإطلاق
...

Sheet 12 — الهيكل التنظيمي
A1: الرمز | B1: الطبقة | C1: من فيها | D1: السلطةُ والاختصاص | E1: التابعُ له | F1: نوعُ العقد
A2: L1 | B2: الطبقةُ الأولى — السلطةُ التنفيذيةُ العليا | C2: الرئيسُ التنفيذي | D2: السلطةُ الأصليةُ بالنظام الأساسي — التوقيعُ والاعتمادُ الأعلى وفتحُ المشاريع وحسمُ المخاطر | E2: لا يعلوه أحد | F2: EXECUTIVE_ROLE
A3: L2 | B3: الطبقةُ الثانية — نوابُ الرئيس التنفيذي | C3: نائبُ العمليات · نائبُ الشؤون المالية والاستثمار · نائبُ الشؤون الإدارية والحوكمة | D3: يمارسون صلاحياتِهم بتفويضٍ ونطاقٍ وسقفٍ معتمد — ولا يملكون السلطةَ الأصلية | E3: الرئيسُ التنفيذي | F3: EXECUTIVE_ROLE
A4: L3 | B4: الطبقةُ الثالثة — الإداراتُ المركزيةُ المتوازية | C4: إحدى عشرةَ إدارةً مركزيةً ومركزٌ رقابيٌّ واحد — لا تتبع إحداها الأخرى | D4: كلٌّ تتبع نائبَها المختصَّ — ومديرُ التشغيلِ واحدٌ منها لا يعلوها | E4: النائبُ المختص | F4: CENTRAL_DEPARTMENT
A5: L4 | B5: الطبقةُ الرابعة — تحت مدير التشغيل: فرعان متوازيان | C5: ◆ الفرعُ الأول: خمسُ إداراتٍ تشغيليةٍ مركزية · ◆ الفرعُ الثاني: مديرو المواقع | D5: الفرعان متوازيان — ولا يتبع مديرُ الموقعِ الإداراتِ التشغيليةَ ولا العكس | E5: مديرُ التشغيلِ لكلا الفرعين | F5: OPERATIONAL_DEPARTMENT + SITE_UNIT
A6: L5 | B6: الطبقةُ الخامسة — الأدوارُ الميدانيةُ داخلَ الموقع | C6: ثمانيةُ أدوارٍ ميدانيةٍ بتبعيةٍ مزدوجة | D6: ◆ هنا يقع التقاطعُ: إداريًّا لمدير الموقعِ وفنيًّا لإدارته المركزية | E6: مديرُ الموقعِ إداريًّا · والإدارةُ المركزيةُ فنيًّا | F6: FIELD_ROLE
A7: L6 | B7: الطبقةُ السادسة — المنفِّذون | C7: المشغّلون والفنيون والعمالُ والسائقون | D7: ينفّذون بتكليفٍ يوميٍّ من دورِ الطبقةِ الخامسةِ المختص | E7: الدورُ الميدانيُّ المختص | F7: FIELD_ROLE
A8: ◆ الحكمُ الحاكم
A9: — | B9: ◆ الفرعان المتوازيان | C9: تحت مديرِ التشغيلِ فرعان لا يتبع أحدُهما الآخر | D9: الفرعُ الأولُ خمسُ إداراتٍ تشغيليةٍ مركزية · والفرعُ الثاني مديرو المواقع | E9: مديرُ التشغيلِ لكليهما | F9: OPERATIONAL + SITE_UNIT
A10: — | B10: التوازي في الطبقة الثالثة | C10: إحدى عشرةَ إدارةً مركزيةً ومركزٌ رقابي | D10: لا تتبع إحداها الأخرى — ومديرُ التشغيلِ واحدٌ منها لا يعلوها | E10: النائبُ المختص | F10: CENTRAL_DEPARTMENT
A11: — | B11: ◆ موضعُ التقاطع | C11: الطبقةُ الخامسةُ داخلَ الموقعِ — أدوارٌ لا إدارات | D11: ثمانيةُ أدوارٍ ميدانيةٍ بتبعيةٍ مزدوجة | E11: مديرُ الموقعِ إداريًّا · والمركزيةُ فنيًّا | F11: FIELD_ROLE

Sheet 13 — التبعية المزدوجة
A1: # | B1: الدورُ الميداني | C1: التبعيةُ الإدارية | D1: التبعيةُ الفنية | E1: ما يقرره الإداريُّ | F1: ما يقرره الفنيُّ | G1: الحكمُ عند التعارض
A2: 1 | B2: مسؤولُ صيانةِ الموقع | C2: مديرُ الموقع | D2: مديرُ الصيانة | E2: الحضورُ والوردياتُ وأذونُ الحركةِ وجدولُ العملِ اليومي | F2: التشخيصُ والحكمُ الفنيُّ وشهادةُ الجاهزيةِ وشجرةُ الأعطال | G2: ◆ لا يُعارَض الحكمُ الفنيُّ بقرارٍ إداريٍّ ولو من مدير الموقع
A3: 2 | B3: مسؤولُ المشغّلينَ في الموقع | C3: مديرُ الموقع | D3: مديرُ القوى التشغيلية | E3: التكليفُ اليوميُّ والورديةُ والحضورُ والانصراف | F3: التأهيلُ والرخصةُ والأهليةُ للمعدةِ وتقييمُ الأداء | G3: لا يُكلَّف مشغّلٌ بمعدةٍ لا يملك أهليتَها
A4: 3 | B4: أمينُ مخزنِ الموقع | C4: مديرُ الموقع | D4: مديرُ المخازن | E4: الصرفُ اليوميُّ والاستلامُ الميدانيُّ وحفظُ العهد | F4: الرصيدُ والتقييمُ والجردُ وسياسةُ إعادة الطلبِ وحدودُه | G4: الرصيدُ لا يُعدَّل ميدانيًّا
A5: 4 | B5: منسّقُ النقلِ في الموقع | C5: مديرُ الموقع | D5: مديرُ النقل والترحيل | E5: طلبُ الترحيلِ وتوقيتُه ميدانيًّا وتأكيدُ الوصول | F5: تخصيصُ الوسيلةِ وأمرُ الترحيلِ وأولوياتُ الأسطول | G5: لا يُصدر أمرَ ترحيلٍ من الموقعِ بلا تخصيصِ الإدارة
A6: 5 | B6: مسؤولُ الشؤون الإداريةِ بالموقع | C6: مديرُ الموقع | D6: الموارد البشريةُ وشؤونُ العاملين بالمشروعات | E6: الإسكانُ والإعاشةُ والانتقالاتُ والحضورُ الإداري | F6: العقدُ والأجرُ والإجازاتُ والتسريحُ والملفُّ الوظيفي | G6: لا يُنهى عقدٌ ولا يُعدَّل أجرٌ ميدانيًّا
A7: 6 | B7: مسؤولُ مشترياتِ الموقع | C7: مديرُ الموقع | D7: إدارةُ المشتريات التشغيلية | E7: طلبُ الاحتياجِ العاجلِ ميدانيًّا واستلامُ التوريد | F7: الترسيةُ وأمرُ الشراءِ والموردُ المعتمدُ والسقوف | G7: لا شراءَ ميدانيٌّ خارجَ سقفٍ معتمدٍ ومورّدٍ مؤهَّل
A8: 7 | B8: ضابطُ بوابةِ الموقع | C8: مديرُ الموقع | D8: الحوكمةُ والالتزام | E8: تسجيلُ الدخولِ والخروجِ ومطابقةُ الأذون | F8: قواعدُ الأذونِ والسريةُ وسجلُّ الاطّلاعِ والاستثناءات | G8: لا يُسمح بدخولٍ بلا إذنٍ ولو بأمرٍ ميداني
A9: 8 | B9: منسّقُ المخاطرِ بالموقع | C9: مديرُ الموقع | D9: إدارةُ المخاطرِ المؤسسية | E9: الإبلاغُ عن الإشاراتِ والوقائعِ وتنفيذُ إجراءاتِ المعالجةِ الميدانية | F9: منهجُ التقييمِ وتصنيفُ الخطرِ ودرجتُه وحدودُ التصعيد | G9: ◆ لا يُصنَّف خطرٌ ولا تُحدَّد درجتُه ميدانيًّا
A10: 9 | B10: مسؤولُ الوقودِ بالموقع | C10: مديرُ الموقع | D10: المخازنُ والتشغيلُ بحسب النموذج | E10: التزويدُ اليوميُّ وقراءةُ العدّادِ وتسجيلُ الاستهلاك | F10: الرصيدُ والمعياريةُ وحدُّ الاستهلاكِ وكشفُ الفروق | G10: الفرقُ فوق الحدِّ يُرفع ولا يُسوَّى ميدانيًّا
A11: ◆ | B11: الحكمُ العام | C11: مديرُ الموقعِ أعلى سلطةٍ ميدانيةٍ إداريًّا | D11: والإدارةُ المركزيةُ أعلى سلطةٍ فنيًّا | E11: الحضورُ والوردياتُ والحركةُ والجدولُ اليومي | F11: التأهيلُ والحكمُ الفنيُّ والرصيدُ والمطابقة | G11: لا يُعارَض الحكمُ الفنيُّ بقرارٍ إداريٍّ ولو من الأعلى

Sheet 14 — تصادم رموز الأفعال
A1: original_code | B1: occurrences | C1: meanings | D1: collision_type | E1: recommended_code | F1: evidence | G1: status
A2: rpt.export | B2: 3 | C2: تصديرُ تقرير | D2: ALIAS — معنًى واحدٌ في شاشاتٍ عدة | E2: finance.report.export | F2: 3 صفًّا بمعنًى واحد: تصديرُ تقرير | G2: resolved — alias معتمد
A3: model.define | B3: 2 | C3: تعريفُ موديلٍ ومواصفاتِه | تعريفُ نموذج عمل | D3: MEANING_COLLISION — معنيان | E3: fleet.model.define · sales.model.define | F3: 2 صفًّا بمعنيين: تعريفُ موديلٍ ومواصفاتِه | تعريفُ نموذج عمل | G3: ◆ حاجبٌ — يُصلَح قبل نقل القاموس
A4: req.raise | B4: 2 | C4: تقديمُ طلبٍ شخصي | رفعُ طلب ترحيل | D4: MEANING_COLLISION — معنيان | E4: transport.request.submit · workspace.request.submit | F4: 2 صفًّا بمعنيين: تقديمُ طلبٍ شخصي | رفعُ طلب ترحيل | G4: ◆ حاجبٌ — يُصلَح قبل نقل القاموس
A5: ◆ الحكم | B5: — | C5: — | D5: لا يُنقل قاموسُ الأفعالِ قبل إغلاق كلِّ MEANING_COLLISION | E5: — | F5: الورقةُ 07 بالفحوصِ الثمانية | G5: الورقةُ 08 خطةُ الترحيل

Sheet 15 — بوابتا الرموز
A1: البوابة | B1: النطاق | C1: ما فُحص | D1: النتيجة | E1: الحالةُ الرسمية | F1: ما يلزم لإغلاقها
A2: Static Gate — الساكنة | B2: الوثيقةُ والقاموسُ بلا كودٍ حيّ | C2: الفحوصُ ① إلى ④ و⑥ و⑦ | D2: ◆ 72 حاجبًا من 362 | E2: Passed with 4 blockers | F2: إصلاحُ MEANING_COLLISION — رمزان بأربعةِ صفوف
A3: Live-Code Gate — الحية | B3: الكودُ العاملُ والمعالجاتُ الحية | C3: الفحصان ⑤ و⑧ | D3: ◐ 362 معلَّقًا | E3: Pending — لم تبدأ | F3: حملةُ الربطِ · ومصفوفةُ استعمالٍ من الكود · وDry Run
A4: ◆ الحكمُ المعلَن | B4: — | C4: — | D4: — | E4: لا يُقال «البوابةُ اجتازت» مطلقًا | F4: بل تُذكر البوابتان منفصلتين — والساكنةُ لا تُغني عن الحية

Sheet 16 — سجل تصحيح الهيكل
A1: # | B1: ما تغيَّر | C1: ما كان | D1: ما صار | E1: الأساسُ والأثر
