Workbook

Sheet الملخص التنفيذي
A1: الملخص التنفيذي — تدقيق نظام إنجاز مقابل الحزمة الحاكمة الست
A2: تدقيق نظام إنجاز (EMS) — شركة تشغيل المعدات · تاريخ التدقيق 2026-08-09 · 595 ملاحظة مؤكَّدة بعد تحقق مضاد مستقل لكل ملاحظة · الدليل من الكود الحي تحت C:\xampp\htdocs\ems
A4: ١ — حجم الفحص
A5: عدد الوثائق الحاكمة المقروءة كاملة | B5: 6 | C5: INJAZ-CORE-01 · INJAZ-DELIVERY-01 · INJAZ-FRD-01 · INJAZ-UX-01 · UXR-01 · M-14 — بإجمالي ٥٧٢١ سطرًا و٩٦٠ كيلوبايت نصًّا
A6: عدد الإدارات المفحوصة | B6: 19 | C6: كل الإدارات المطلوبة، ومنها مساحة عملي والمراجع الداخلي المستقل
A7: عدد ملفات الكود المفحوصة | B7: 2170 | C7: PHP · JS · CSS · SQL · Migrations — باستثناء vendor و.git
A8: عدد الشاشات المجرودة | B8: 491 | C8: ٣٩٣ مربوطة بالسايدبار · ٩٨ يتيمة · ٤٦٤ نقطة API/AJAX
A9: عدد معالجات الكتابة المفحوصة | B9: 174 | C9: من ٥٥ معالج فعل رئيسًا + نقاط CMP-03
A10: عدد الأحداث المفحوصة | B10: 103 | C10: ٦٥ موضع نشر في الإنتاج · ٨٥ حدثًا بلا مستهلك
A12: ٢ — نتيجة التدقيق
A13: إجمالي الملاحظات المؤكَّدة | B13: =COUNTA('السجل الجامع'!$A$5:$A$599) -> 595 | C13: بعد إسقاط ٩٥ ملاحظة سقطت في التحقق المضاد (شيت «مرفوضة بعد التحقق»)
A14: P0 — حاجب إطلاق | B14: =COUNTIF('السجل الجامع'!$K$5:$K$599,"P0") -> 13 | C14: أثر مالي أو قانوني ينفَّذ بلا تفويض · تسريب بيانات · فقدان مصدر الحقيقة · شاشة حاكمة غائبة
A15: P1 — خطر جوهري | B15: =COUNTIF('السجل الجامع'!$K$5:$K$599,"P1") -> 103
A16: P2 — مهم | B16: =COUNTIF('السجل الجامع'!$K$5:$K$599,"P2") -> 294
A17: P3 — متوسط | B17: =COUNTIF('السجل الجامع'!$K$5:$K$599,"P3") -> 180
A18: P4 — تحسين | B18: =COUNTIF('السجل الجامع'!$K$5:$K$599,"P4") -> 5
A19: ملاحظات تمنع الإطلاق | B19: =COUNTIF('السجل الجامع'!$S$5:$S$599,"نعم") -> 308
A20: ملاحظات تمنع العرض الخارجي | B20: =COUNTIF('السجل الجامع'!$T$5:$T$599,"نعم") -> 390
A21: مؤكَّدة بالتحقق المضاد | B21: =COUNTIF('السجل الجامع'!$W$5:$W$599,"مؤكَّدة") -> 447 | C21: المحقق فتح الملف عند السطر المذكور وأثبت الادعاء
A22: مرجَّحة (صحيحة جوهرًا · صياغة أو خطورة عُدِّلت) | B22: =COUNTIF('السجل الجامع'!$W$5:$W$599,"مرجَّحة") -> 148
A24: ٣ — أضعف الإدارات (بعدد P0+P1)
A25: إدارة الحوكمة والالتزام | B25: 16 | C25: من إجمالي 77 ملاحظة في هذه الإدارة
A26: التمويل والملكية | B26: 11 | C26: من إجمالي 27 ملاحظة في هذه الإدارة
A27: المالية والخزينة | B27: 9 | C27: من إجمالي 41 ملاحظة في هذه الإدارة
A28: المشتريات التشغيلية | B28: 8 | C28: من إجمالي 42 ملاحظة في هذه الإدارة
A29: إدارة التشغيل | B29: 7 | C29: من إجمالي 26 ملاحظة في هذه الإدارة
A30: النقل والترحيل | B30: 7 | C30: من إجمالي 44 ملاحظة في هذه الإدارة
A32: ٤ — أكثر الوثائق عدمَ تطبيق
A33: M-14 | B33: 174
A34: INJAZ-FRD-01 | B34: 156
A35: INJAZ-UX-01 | B35: 131
A36: INJAZ-CORE-01 | B36: 59
A37: UXR-01 | B37: 39
A38: INJAZ-DELIVERY-01 | B38: 36
A40: ٥ — أكثر العيوب تكرارًا
A41: Permission Gap | B41: 97
A42: Governance Gap | B42: 68
A43: UX/UI Defect | B43: 68
A44: Missing Screen | B44: 58
A45: Missing Evidence | B45: 48
...

Sheet السجل الجامع
A1: السجل الجامع النهائي — 595 ملاحظة مرقَّمة بلا تكرار
A2: تدقيق نظام إنجاز (EMS) — شركة تشغيل المعدات · تاريخ التدقيق 2026-08-09 · 595 ملاحظة مؤكَّدة بعد تحقق مضاد مستقل لكل ملاحظة · الدليل من الكود الحي تحت C:\xampp\htdocs\ems
A4: رقم الملاحظة | B4: الوثيقة | C4: بند الوثيقة | D4: الإدارة | E4: اسم الشاشة | F4: رابط الشاشة | G4: مجموعة السايدبار | H4: المتوقَّع حسب الوثيقة | I4: الواقع في النظام | J4: نوع الفجوة | K4: الخطورة | L4: الأثر | M4: السبب الجذري | N4: الدليل (ملف:سطر) | O4: لقطة الشاشة | P4: خطوات إعادة الإنتاج | Q4: الإصلاح الموصى به | R4: المالك المقترح | S4: يمنع الإطلاق | T4: يمنع العرض الخارجي | U4: اختبار القبول | V4: الحالة | W4: نتيجة التحقق المضاد | X4: ملاحظة المحقق | Y4: الخطورة قبل التحقق | Z4: الإصلاح قابل للتنفيذ | AA4: الاختبار قابل للتشغيل | AB4: ملف التدقيق | AC4: تصنيف الفجوة | AD4: حالة الإغلاق
A5: INJ-0001 | B5: INJAZ-FRD-01 | C5: INJAZ-FRD-01 §١١-٣ · المرحلة ٣ — مراجعةُ العقد وتوقيعُه | D5: المبيعات والعقود | E5: عقود العملاء | F5: http://localhost/ems/Contracts/contracts.php | G5: ثالثًا: مراجعة العقد وتوقيعه | H5: دورةُ الإدارة: «سجلُّ عميلٍ ← عرضُ سعرٍ ← عقدٌ نافذٌ ← تغطيةٌ ووحداتٌ وأحكامٌ ← أداءٌ شهريٌّ ← مستخلصٌ ← مطالبة»، ومخرَجُ المرحلة الثالثة «عقدٌ نافذ» يعتمده «المخوَّلُ ضمن سقفِه ويُرفع للرئيس التنفيذيِّ إن تجاوز السقفَ». | I5: العمودُ الحاكمُ لحالة العقد `contracts.contract_status` (آلةُ الحالة الاثنتا عشرةَ حالة) لا يكتبه إلا `app/Services/Contract/ContractStateMachine`، ومستدعيها الوحيدُ في المستودع كلِّه هو `Portal/ceo_contracts.php:167`. وشاشةُ «عقود العملاء» — الشاشةُ الأمُّ للإدارة — لا تذكر `contract_status` ولا مرةً واحدة، ولا تملك فعلًا لنقل العقد من «مسودة» إلى «تفاوض» إلى «معتمد». | J5: Wrong Workflow | K5: P0 | L5: لا يوجد في النظام مسارٌ لجعلِ عقدٍ «معتمدًا»، وشاشةُ توقيع القمة تقرأ `WHERE contract_status='معتمد'` — فقائمةُ العقود القابلة للتوقيع تبقى فارغةً أبدًا ولا يمكن توقيعُ عقدٍ واحدٍ من داخل النظام. وبلا «نافذ» لا تُفتح حاويةُ تشغيلٍ (`OperationalTransformService::isEffective`) فتنقطع السلسلةُ كلُّها من أولها. | M5: آلةُ حالةٍ بُنيت كاملةً وربطت بنقطة اختناقٍ واحدةٍ في شاشة القمة، ولم تُزرع أفعالُها (تقديمٌ للمراجعة · اعتماد) في شاشة العقود المالكة. | N5: app/Services/Contract/ContractStateMachine.php:148; :219; Portal/ceo_contracts.php:167; Portal/ceo_contracts.php:243-246; Contracts/contracts.php:1; app/Services/Operations/OperationalTransformService.php:76 | P5: ١) ادخل بدور 12 وأنشئ عقدًا من Contracts/contracts.php. ٢) ابحث عن زرِّ «رفع للمراجعة» أو «اعتماد» ⇒ لا يوجد وحالةُ العقد تبقى NULL. ٣) ادخل بدور 9 وافتح Portal/ceo_contracts.php ⇒ قائمةُ «العقود القابلة للتوقيع» فارغة. | Q5: أضِف في `Contracts/contracts.php` فعلَين محروسَين يستدعيان `ContractStateMachine::transition()`: «رفع للتفاوض» (DRAFT→NEGOTIATION) و«اعتماد» (NEGOTIATION→APPROVED) بحارسِ سقفٍ يقارن قيمةَ العقد بسقف المخوَّل ويُصعّد تلقائيًّا عند التجاوز، واعرِض عمودَ `contract_status` في الشبكة. | R5: فريق الباك-إند — وحدة العقود | S5: نعم | T5: نعم | U5: مستخدمُ المبيعات ينقل عقدًا من مسودة إلى معتمد بفعلين مسجَّلين، ويظهر العقدُ فورًا في قائمة التوقيع لدى القمة. | V5: مفتوح | W5: مؤكَّدة | X5: بحثٌ شاملٌ عن `ContractStateMachine::transition` يُرجع مستدعيًا إنتاجيًّا واحدًا هو Portal/ceo_contracts.php:167 وهو ينقل إلى SIGNED حصرًا، وجدولُ TRANSITIONS يشترط APPROVED قبله، ولا موضعَ في المستودع يكتب «تفاوض» أو «معتمد» (schema.sql:1853 يجعل contract_status DEFAULT NULL، وContracts/contracts.php لا يذكر العمود)؛ فسلسلةُ مسودة→تفاوض→معتمد→موقَّع→نافذ لا تكتمل، وOperationalTransformService.php:76 يمنع فتحَ أيِّ حاويةٍ تبعًا لذلك. | Y5: P0 | Z5: نعم | AA5: نعم | AB5: 02_FRD | AC5: فجوة تنفيذ (Implementation) | AD5: Decision Closed · Implementation Open
A6: INJ-0002 | B6: M-14 | C6: PR-05 · «إخفاءُ الزرِّ تحسينُ تجربةٍ لا حماية» — الحارسُ قبل الكتابة | D6: إدارة الموردين | E6: طلب العروض ومقارنتها (الترسية) | F6: http://localhost/ems/Procurement/rfq_compare_award.php | G6: ثالثًا: طلب العروض والترسية | H6: الحارسُ في الخادمِ يسبق الأثرَ؛ والترسيةُ قرارٌ ماليٌّ يُحرَس بصلاحيةٍ وسقفٍ ومرجعِ تفويض. | I6: صحيحٌ عدا وصفِ حقنِ SQL: القيمُ مُمَرَّرةٌ بـintval/floatval/mysqli_real_escape_string فلا حقنَ عمليًّا — والخللُ هو الأثرُ قبل الحارس وغيابُ فحصِ can_edit. — [مُصحَّح بعد التحقق] الصياغة الأولى: الشاشةُ الوحيدةُ في مجموعة «ثالثًا: طلب العروض والترسية» لدى دور الموردين تنفّذ الترسيةَ في معالجٍ يبدأ في السطر 20: يُدرج `INSERT INTO rfq_awards` في السطر 33 ويحدّث `UPDATE supplier_rfqs SET state=' | J6: Permission Gap | K6: P0 | L6: أيُّ مستخدمٍ مسجَّلِ الدخول يُرسي أيَّ طلبِ عروضٍ على أيِّ موردٍ بأيِّ سعرٍ ثم يُعاد توجيهُه برسالة «لا تملك صلاحية» بعد استقرار الترسية — وهي أخطرُ نقطةِ تسريبٍ ماليٍّ في وحدة الموردين. والاستعلاماتُ مبنيةٌ بدمجٍ نصيٍّ مباشرٍ للمتغيرات. | M6: ترتيبُ الملف: المعالجُ في الأعلى والحارسُ في الأسفل مع تضمين السايدبار، مع كتابةٍ خامٍّ بـmysqli بلا بوابة العزل. | N6: Procurement/rfq_compare_award.php:20; :26; :33-36; :37-38; :66 | P6: ١) ادخل بحسابٍ بلا أيِّ منحةٍ على الشاشة. ٢) أرسل POST بـ award_quote=<quote_id> و award_reason=نص. ٣) لاحظ رسالةَ الرفض، ثم افحص rfq_awards و supplier_rfqs ⇒ الترسيةُ مسجَّلةٌ والحالةُ awarded. | Q6: انقل إلى أعلى `Procurement/rfq_compare_award.php` (قبل السطر 20) كتلةَ `check_page_permissions($conn,'Procurement/rfq_compare_award.php')` مع منعِ POST بلا can_edit، وحوّل الكتابتين إلى `ems_tenant_db()` بعباراتٍ مُعدَّة، وأضِف فحصَ سقفٍ عبر `AuthorityGuard::sign()` بقيمة الترسية. | R6: فريق الباك-إند — وحدة المشتريات والموردين | S6: نعم | T6: نعم | U6: POST إلى الشاشة بحسابٍ بلا can_edit لا ينشئ صفَّ ترسيةٍ ولا يغيّر حالةَ الطلب، ويُسجَّل الرفض. | V6: مفتوح | W6: مؤكَّدة | X6: معالجُ POST في السطر 20 ينفّذ INSERT INTO rfq_awards (33-37) وUPDATE supplier_rfqs SET state='awarded' (38-39) قبل include '../insidebar.php' في السطر 66 حيث الحارسُ الوحيد؛ والموديول 298 مسجَّلٌ لكن مصفوفةَ الصلاحيات تمنح الأدوار 16 و2 و8 can_view فقط ولا تمنح can_add/can_edit لأيِّ دور — فأيُّ مستخدمٍ مصادَقٍ يُرسي ترسيةً لا يملكها أحد. | Y6: P0 | Z6: نعم | AA6: نعم | AB6: 06_M14 | AC6: فجوة تنفيذ (Implementation) | AD6: Decision Closed · Implementation Open
A7: INJ-0003 | B7: INJAZ-CORE-01 | C7: PR-01 · مصدرُ الحقيقة الواحد — «ولا يُدخَل بيانٌ مرتين في شاشتين مختلفتين» | D7: التمويل والملكية | E7: نماذج التمويل ومعالجتها | F7: http://localhost/ems/Financing/fin_models.php | G7: أولًا: النموذج والممول | H7: «لكل بيانٍ موضعٌ واحدٌ يُنشأ فيه ويُعدَّل، وكلُّ عرضٍ آخرَ له قراءةٌ لا نسخة»؛ ونموذجُ التمويل هو أولُ مستندٍ في دورة الإدارة («نموذج بمعالجته») ولا اعتمادَ لعمليةٍ بلا نموذج. | I7: شاشةُ «نماذج التمويل ومعالجتها» تكتب وتقرأ من scr_fin_models عبر cmp03_store_insert/cmp03_store_rows (الأسطر 28 · 80 · 87)، بينما جدولُ المجال الحقيقيُّ financing_models هو الذي يقرؤه منشئُ العملية: Financing/financing_operation_new.php:62 يملأ قائمةَ النماذج منه، و FinancingService::createOperation:169 يتحقق من وجود النموذج فيه ويرفض 422 إن لم يجده. | J7: Data Mismatch | K7: P0 | L7: نموذجٌ يُنشأ من الشاشة المخصَّصة له لا يظهر أبدًا في قائمة إنشاء عملية التمويل، وإنشاءُ العملية به يُرفض برسالة «نموذج تمويل غير معرَّف» — فالمرحلةُ الأولى من دورة الإدارة معطَّلةٌ عمليًّا ولا سبيلَ لإضافة نموذجٍ إلا بإدخالٍ مباشرٍ في القاعدة. | M7: موجةُ CMP-03 وجّهت الشاشةَ إلى المخزن البيني scr_* ولم تُوصل بجدول المجال القائم financing_models. | N7: Financing/fin_models.php:28; Financing/fin_models.php:80; Financing/fin_models.php:87; includes/cmp03_registry.php:252; includes/cmp03_registry.php:254; Financing/financing_operation_new.php:62; app/Services/Financing/FinancingService.php:169; app/Services/Financing/FinancingService.php:174 | P7: ١) بدور ٢٦ افتح «نماذج التمويل ومعالجتها» وأضِف نموذجًا برمزٍ جديدٍ واعتمده. ٢) افتح «إنشاء عملية تمويل» → النموذجُ غيرُ موجودٍ في القائمة. ٣) أرسل الرمزَ يدويًّا في الطلب → يُرفض 422 «نموذج تمويل غير معرَّف». | Q7: غيّر خريطةَ 'fin_models.php' في includes/cmp03_registry.php:252 لتشير إلى جدول financing_models بأعمدته الدلالية، أو استبدل معالجَ الحفظ في Financing/fin_models.php:80 بكتابةٍ مباشرةٍ في financing_models عبر بوابة العزل. | R7: فريق الباك-إند — وحدة التمويل | S7: نعم | T7: نعم | U7: نموذجٌ يُضاف من الشاشة يظهر فورًا في قائمة إنشاء العملية، وإنشاءُ عمليةٍ به ينجح؛ وصفرُ صفٍّ جديدٍ في scr_fin_models. | V7: مفتوح | W7: مؤكَّدة | X7: محقَّقٌ بالكامل: includes/cmp03_registry.php:252-254 يربط `fin_models.php` بجدول `scr_fin_models`، بينما Financing/financing_operation_new.php:62 وFinancingService::createOperation:169-174 يقرآن `financing_models` ويرفضان 422 بلا نموذج — ولا يوجد في المستودع كلِّه أيُّ INSERT في `financing_models` (ولا بذرةٌ في database/seeds خارج قائمة الملء الآلي) — فإنشاءُ أيِّ عمليةِ تمويلٍ متعذّرٌ بنيويًّا والشاشةُ الحاكمةُ تكتب في جدولٍ موازٍ لا يقرؤه أحد. | Y7: P0 | Z7: نعم | AA7: نعم | AB7: 01_CORE | AC7: فجوة تنفيذ (Implementation) | AD7: Decision Closed · Implementation Open
A8: INJ-0004 | B8: M-14 | C8: §٢٧ · الحقلُ الحساس — «لا يُعرض ولا يُصدَّر إلا بمنحٍ فردي» | D8: الموارد البشرية | E8: سجل الموظفين | F8: http://localhost/ems/Employees/employees.php | G8: ثانيًا: التعاقد والمباشرة | H8: «الحقلُ الحساس | حقلٌ لا يُعرض ولا يُصدَّر إلا بمنحٍ فردي | ليس المخفيَّ» — والراتبُ من الحقول التي تفرض M-14 على الموارد البشرية «قراءةً مسجَّلة» عليها (SCN-872). | I8: السطرُ 982 عمودُ ترشيحٍ لـ«نوع الراتب» لا عمودُ راتبٍ في الجدول؛ ومنفذُ الكشف الحقيقيُّ get_employee_data.php الذي يرسل الصفَّ كاملًا (بما فيه monthly_salary ورقمُ الهوية) لأيِّ جلسةٍ مصادَقةٍ بلا فحصِ صلاحيةٍ إطلاقًا. — [مُصحَّح بعد التحقق] الصياغة الأولى: شاشةُ سجل الموظفين تعرض وتحفظ monthly_salary و salary_type مباشرةً (الإدخالُ في السطر 92 والحقلُ في 724 وعمودُ الجدول في 982) لكل من يملك can_view/can_edit على الوحدة، بلا أي فحصِ منحةٍ فرديةٍ وبلا سط | J8: Permission Gap | K8: P0 | L8: راتبُ كل موظفٍ مكشوفٌ في الشاشة الأكثر استعمالًا في الإدارة لكل من يملك عرضَ سجل الموظفين، بينما البيانُ نفسُه محجوبٌ في بطاقة الموظف؛ فالحجبُ يُلتفّ عليه بفتح الشاشة الأخرى، ولا يُسجَّل الاطّلاع. | M8: طُبِّق حارسُ الرؤية على شاشةٍ واحدةٍ (بطاقة الموظف) ولم يُعمَّم على شاشة السجل التي تعرض الحقلَ نفسَه. | N8: Employees/employees.php:92,724,1376; Employees/get_employee_data.php:8-13,31-50; Employees/employee_card.php:164-175 | P8: ١) ادخل بحسابٍ يملك عرضَ سجل الموظفين وبلا صلاحية الأجور. ٢) افتح «سجل الموظفين» → عمودُ «نوع الراتب» وقيمةُ الراتب في نموذج التعديل ظاهرة. ٣) افتح بطاقةَ الموظف نفسِه → تبويبُ الأجور محجوب. ٤) ابحث عن سطر اطّلاع → لا يوجد. | Q8: في Employees/employees.php لفَّ حقلَ monthly_salary وعمودَه بفحص VisibilityGuard::check('card.payroll') كما في employee_card.php:164، ولا تُرسل القيمةَ في HTML لغير المخوَّل، وسجّل الاطّلاعَ عبر ems_log_sensitive_read لمن يراها. | R8: فريق الحوكمة — وحدة الصلاحيات | S8: نعم | T8: نعم | U8: حسابٌ بلا صلاحية الأجور لا يجد قيمةَ الراتب في جسم استجابة سجل الموظفين ولا في نموذج التعديل؛ ومن يراها يُكتب له سطرُ اطّلاع. | V8: مفتوح | W8: مؤكَّدة | X8: مؤكَّدٌ بل أشدّ: employees.php يحفظ monthly_salary (:92) ويعرض حقلَه (:724) بلا أيِّ VisibilityGuard أو ems_log_sensitive_read (بحثٌ = صفر)، والأخطرُ أن Employees/get_employee_data.php:31-50 يعيد صفَّ employees كاملًا (الراتبُ والهوية) لأيِّ مستخدمٍ مصادَقٍ بلا أيِّ فحصِ موديول — بينما employee_card.php:164-175 يحجب التبويبَ نفسَه بـVG::check ويسجّل الاطّلاع. | Y8: P0 | Z8: نعم | AA8: نعم | AB8: 06_M14 | AC8: فجوة تنفيذ (Implementation) | AD8: Decision Closed · Implementation Open
A9: INJ-0005 | B9: INJAZ-CORE-01 | C9: PR-05 · الحارسُ في الخادم · ٤-١ المبادئُ الاثنا عشرَ الحاكمة | D9: إدارة الحوكمة والالتزام | E9: طبقة الصلاحيات المشتركة | F9: http://localhost/ems/includes/permissions_helper.php | G9: - | H9: «كلُّ منعٍ يُنفَّذ في الخادم قبل الحفظ … والنداءُ المخالفُ يُرفض ولو جاء بمساره مباشرةً أو من أداةٍ خارجية — ويُسجَّل الرفضُ بالمستخدم والوقت والرمز». | I9: get_current_page_permissions() تُرجع can_view/add/edit/delete = true حين لا تُحَلّ الشاشةُ إلى موديول (id = null)، و_default_full_permissions() تفعل الشيءَ نفسه، وenforce_current_page_view_permission() لا تحجب إلا حين id !== null. الصمّامُ المضادّ ems_failclosed_screen_guard مقودٌ بـEMS_FAILCLOSED_ENFORCE_PREFIXES وهو فارغٌ افتراضيًّا. النتيجة: أيُّ شاشةٍ غيرِ مسجَّلةٍ في modules مفتوحةٌ لكل مستخدمٍ بصلاحياتٍ كاملة. | J9: Permission Gap | K9: P0 | L9: الافتراضُ المركزي في النظام هو «السماح عند الجهل» — عكسُ PR-05 نصًّا. وكلُّ شاشةٍ جديدةٍ تُنشَر قبل تسجيلها موديولًا تكون مفتوحةً للجميع بلا رفضٍ ولا سجل. وهذا هو الجذرُ الذي يجعل عشراتِ الملاحظات في هذا التقرير قابلةً للاستغلال. | M9: قرارُ توافقيةٍ قديم: أُريد ألّا تنكسر شاشاتٌ موروثةٌ غيرُ مسجَّلة، فجُعل الافتراضُ مفتوحًا بدل تسجيلِ الشاشات. | N9: includes/permissions_helper.php:621; :622; :810; :811; :766; :793 | P9: ١) أنشئ ملفًا جديدًا تحت Settings/ يستدعي get_current_page_permissions ويطبع النتيجة. ٢) لا تسجّله في modules. ٣) افتحه بأيِّ حسابٍ ⇐ can_view وcan_add وcan_edit وcan_delete كلُّها true. | Q9: قلبُ الافتراض في includes/permissions_helper.php:621-629 و810-818 إلى صلاحياتٍ صفريةٍ (كلُّها false) مع تسجيلِ رفضٍ باسم الشاشة، وتشغيلُ ems_failclosed_screen_guard على كلِّ البادئات افتراضيًّا، وإضافةُ فاحصٍ في الإصدار يمنع نشرَ ملفِّ شاشةٍ غيرِ مسجَّلٍ في modules. | R9: مكتب الهندسة — طبقة الحراس المشتركة | S9: نعم | T9: نعم | U9: شاشةٌ غيرُ مسجَّلةٍ في modules تُعيد 403 لكل الأدوار عدا السوبر، وتكتب صفَّ رفضٍ فيه المستخدمُ والوقتُ والرمز. | V9: مفتوح | W9: مؤكَّدة | X9: تحققتُ حرفيًّا: get_current_page_permissions (621-629) تُرجع الأربعَ true حين لا تُحَلّ الشاشة، و_default_full_permissions (810-818) مثلُها، و enforce_current_page_view_permission لا يحجب إلا حين id !== null (770)، والصمّامُ مقودٌ بـEMS_FAILCLOSED_ENFORCE_PREFIXES الفارغِ افتراضًا (والوثيقةُ docs/SUPPLIERS_DEPARTMENT_AUDIT_REPORT_ar.md:323 تقتبس .env:53 فارغًا). والأثرُ حيٌّ لا نظري: نحوُ ٤٠ شاشةً تضمّن insidebar وغيرُ مسجَّلةٍ في modules — منها Clients/client_profile.php و Suppliers/supplier_profile.php و Financing/operation_profile.php و Timesheet/aprovment.php — مفتوحةٌ لكل مصادَقٍ بصلاحياتٍ كاملة. | Y9: P0 | Z9: نعم | AA9: نعم | AB9: 01_CORE | AC9: فجوة تنفيذ (Implementation) | AD9: Decision Closed · Implementation Open
A10: INJ-0006 | B10: M-14 | C10: TABLE 46 (لأفعال التصدير) · ▐ ٨-٤ | D10: إدارة الحوكمة والالتزام | E10: مركز التقارير / التصدير الموحَّد | F10: http://localhost/ems/excel.php | G10: متابعة وتقارير الحوكمة | H10: «صلاحيةُ التصديرِ + حدُّ الحقولِ الحساسة — لأفعال audit.export · rpt.export»، أي صلاحيةُ تصديرٍ مستقلةٌ عن صلاحية العرض، وحجبُ الحقول الحساسة في الملف. | I10: فرعُ الفشلِ المفتوح حيٌّ لا نظري: لا مسارَ في excel.php يحمّل permissions_helper.php، ولا يلتقطه حارسُ AJAX المركزي (اسمُ السكربت ليس get_*/‏*_handler)، فالتصديرُ محكومٌ بعزل الشركة وحدَه دون أيِّ راية دور. — [مُصحَّح بعد التحقق] الصياغة الأولى: excel.php يفحص وجودَ الجلسة فقط، وExcelService::authorize يفحص can_view (صلاحيةَ عرضٍ لا تصدير). والأسوأ: `if (!function_exists('check_page_permissions')) { return; }` يجعل الفحصَ يفشل مفتوحًا إن لم ي | J10: Permission Gap | K10: P0 | L10: من يملك عرضَ شاشةٍ يملك تصديرَها كاملةً بحقولها الحساسة — وهو عكسُ الحكم صراحةً: «فقد يملك المستخدمُ حقَّ التصديرِ لجزءٍ دون عرضِ بعضِ الحقولِ أو العكس — صلاحيتان منفصلتان لا واحدة». الحقلُ الحساس يُسجَّل اطّلاعُه ثم يُسلَّم في الملف. | M10: نموذج الصلاحيات رباعيُّ الأفعال (view/add/edit/delete) بلا فعلِ export، وصنفُ Column بلا خاصيةِ حساسية. | N10: excel.php:16; :65; :99; app/Services/Excel/ExcelService.php:61-63; :91; :150-158 | P10: ١) امنح دورًا can_view على كيانٍ فيه حقلٌ مصنَّف حساسًا في scr_sensitive_fields. ٢) صدّر الكيان من الشاشة. ٣) افتح الملف ⇐ الحقلُ الحساس ظاهرٌ بقيمته. | Q10: إضافة عمودٍ can_export إلى role_permissions وفحصُه في app/Services/Excel/ExcelService::authorize() بدل can_view، وحذفُ فرع الفشلِ المفتوح في السطر 61-63، وتصفيةُ الأعمدة في Exporter::write وفق نتيجة استعلام scr_sensitive_fields بدل الاكتفاء بتسجيلها. | R10: فريق الباك-إند — وحدة الحوكمة والصلاحيات | S10: نعم | T10: نعم | U10: دورٌ بـcan_view وبلا can_export يُرفض تصديرُه 403؛ ودورٌ بـcan_export بلا منحةِ حقلٍ حساس يحصل على ملفٍّ بلا ذلك العمود. | V10: مفتوح | W10: مؤكَّدة | X10: أشدُّ ممّا وُصف: excel.php لا يحمّل includes/permissions_helper.php إطلاقًا (config.php لا يضمّنه) فشرطُ function_exists يفشل ويعود authorize() بلا فحص — تصديرُ أيِّ كيانٍ متاحٌ لأيِّ حسابٍ مسجَّل، وهو تسريبُ بياناتٍ بين الإدارات. | Y10: P1 | Z10: نعم | AA10: نعم | AB10: 06_M14 | AC10: فجوة تنفيذ (Implementation) | AD10: Decision Closed · Implementation Open
A11: INJ-0007 | B11: M-14 | C11: ▐ ١١-١ الحوكمةُ والملكيةُ والحدود · ما لا تملكه: أيَّ قرارٍ تشغيليٍّ | D11: إدارة الحوكمة والالتزام | E11: صفحات النظام والإدارات / الأدوار وقوالب صلاحياتها | F11: http://localhost/ems/Settings/modules.php | G11: رابعًا: الظهور والبوابة والصفحات | H11: الحوكمة والالتزام تملك «الكياناتِ · التفويضَ · قوالبَ الصلاحيات · مفاتيحَ الظهور · مكوّناتِ البوابة · صفحاتِ النظام · الحساب» — وهي وحدَها مَن يملك هذه السجلات؛ وإدارةُ التشغيل إدارةٌ تشغيليةٌ لا حوكمية. | I11: check_page_permissions (112 شاشة) تفشل مغلقةً منذ 2026-08-05، فالفشلُ المفتوحُ محصورٌ في get_current_page_permissions وستِّ شاشاتٍ تستعملها — لكن منها Settings/role_permissions.php وSettings/roles.php وmain/users.php، فسلسلةُ التصعيد مكتملةٌ ومن أخطر ما يكون. — [مُصحَّح بعد التحقق] الصياغة الأولى: الدالة ems_governance_admin_roles() تُرجع الدورين 1 (ادارة التشغيل) و15 (مدير الصلاحيات)، وems_require_governance_screen ترجع لهما صلاحياتٍ كاملةً (can_view/add/edit/delete = true) قبل أيِّ استعلامِ م | J11: Wrong Owner | K11: P0 | L11: مديرُ التشغيل يستطيع حذفَ صفِّ موديولٍ من سجل الشاشات — والشاشةُ غيرُ المسجَّلة تصير مفتوحةً للجميع بسبب الفشل المفتوح في permissions_helper. مسارُ تصعيدِ امتيازٍ مكتمل من دورٍ تشغيليٍّ إلى فتحِ أيِّ شاشةٍ في النظام. | M11: تعليقُ الملف يشرح السبب صراحةً: «الشركةُ 1 ليس فيها أيُّ حسابٍ بالدور 15 — أرضيةٌ بالدور 15 وحدَه تقفلها خارج نظامها». عولجت مشكلةُ بياناتٍ بتوسيعِ أرضيةِ الصلاحية في الكود بدل إنشاء حسابِ حوكمة. | N11: includes/governance_guard.php:42,71,94-97; Settings/modules.php:20-21; includes/permissions_helper.php:614-628; Settings/role_permissions.php:21-28; Settings/roles.php:17-25; main/users.php:32 | P11: ١) ادخل بدور 1 (ادارة التشغيل). ٢) افتح http://localhost/ems/Settings/modules.php ⇐ تُفتح بصلاحياتٍ كاملة. ٣) احذف صفَّ موديولٍ لشاشةٍ ما. ٤) ادخل بأيِّ دورٍ آخر وافتح تلك الشاشة ⇐ تُفتح بصلاحياتٍ كاملة بسبب _default_full_permissions. | Q11: حصرُ ems_governance_admin_roles() في EMS_ROLE_PERMISSIONS_MGR وحدَه في includes/governance_guard.php:42، وإنشاءُ حسابِ حوكمةٍ بالدور 15 في كل شركةٍ ضمن هجرةِ بياناتٍ بدل توسيع الأرضية، وإبقاءُ الدور 1 عارضًا بمنحةٍ صريحةٍ إن لزم. | R11: فريق الباك-إند — وحدة الحوكمة والصلاحيات | S11: نعم | T11: نعم | U11: الدور 1 يُرفض 403 عند فتح Settings/modules.php ما لم تُمنَح له can_view صراحةً، ولا يملك can_delete عليه في أيِّ حال؛ ويُسجَّل الرفضُ في سجل الأمن. | V11: مفتوح | W11: مؤكَّدة | X11: مؤكَّدٌ بالكامل: governance_guard.php:42 يُرجع array(EMS_ROLE_OPERATIONS_MGR, EMS_ROLE_PERMISSIONS_MGR) أي '1' و'15'، وems_require_governance_screen:96-97 تعيد لهما $full (كلُّ الصلاحيات) قبل أيِّ استعلامِ منح، وSettings/modules.php:21 هي هذه البوابةُ نفسُها. وسلسلةُ التصعيد قائمةٌ فعلًا: get_current_page_permissions (permissions_helper.php:621-628) تفشل مفتوحةً، وSettings/role_permissions.php:21-28 يشترط $rp_perms['id'] !== null قبل المنع — فحذفُ صفِّ الموديول 123 من داخل modules.php يفتح شاشةَ منحِ الصلاحيات للجميع. | Y11: P0 | Z11: نعم | AA11: نعم | AB11: 06_M14 | AC11: فجوة تنفيذ (Implementation) | AD11: Decision Closed · Implementation Open
A12: INJ-0008 | B12: M-14 | C12: BR-GOV-01 · الحارسُ المركزي · CORE PR-05/AR-05 | D12: إدارة الحوكمة والالتزام | E12: حارس الصلاحيات المركزي | G12: - | H12: CORE AR-05: «المنعُ يُنفَّذ ثلاثَ مرات … والحارسُ في الخادم يرفض النداءَ ولو جاء بمساره مباشرةً» — والحارسُ **مغلقٌ افتراضًا** (fail-closed). | I12: الحارسُ المركزيُّ مفتوحٌ افتراضًا: `_default_full_permissions()` تُرجع `can_view/can_add/can_edit/can_delete = true` لأيِّ شاشةٍ غيرِ مسجَّلةٍ في `modules` (`includes/permissions_helper.php:810-818`)، وتُستدعى مرتين: عند فشلِ تجهيزِ الاستعلام (`:897-899`) وعند عدمِ العثورِ على الشاشة (`:909-911`). والنمطُ نفسُه في `get_current_page_permissions` (`:621-629`). والتعليقُ يقرُّ بذلك: «إذا لم توجد الصفحة في قاعدة البيانات تُرجع كل الصلاحيات للتوافقية». | J12: Permission Gap | K12: P0 | L12: أيُّ شاشةٍ جديدةٍ أو مُعادةِ التسميةِ أو غيرِ مسجَّلةٍ تُمنح تلقائيًّا صلاحياتٍ كاملةً لكلِّ الأدوار — إضافةً وتعديلًا وحذفًا. ونسيانُ صفٍّ واحدٍ في `modules` يفتح شاشةً حاكمةً للجميع. وفشلُ الاستعلامِ نفسُه (خطأُ قاعدة) يفتح كلَّ شيء. | M12: قرارُ «توافقيةٍ» مع شاشاتٍ قديمةٍ غيرِ مسجَّلةٍ بقي في المسارِ الحرِج بدل هجرةِ تلك الشاشاتِ وإغلاقِ الحارس. | N12: includes/permissions_helper.php:803; :810; :813; :816; :818; :897; :898; :909; :910; :621; :624; :628 | P12: ١) أنشئ ملفًّا `Test/unregistered.php` يستدعي `check_page_permissions($conn,'Test/unregistered.php')`. ٢) لا تُسجّله في `modules`. ٣) افتحه بأيِّ دور: القيمُ الأربعُ `true`. ٤) كرِّر بعد قطعِ الاتصالِ بالقاعدةِ فيفشل `prepare`: النتيجةُ نفسُها (`:897-899`). | Q12: اقلِب الافتراضَ في `includes/permissions_helper.php`: اجعل `_default_full_permissions()` تُرجع الأربعَ `false` (وأعِد تسميتَها `_default_denied_permissions`)، وسجِّل حدثَ أمنٍ `PERM_UNREGISTERED_SCREEN`؛ وفي حالةِ فشلِ `prepare` (`:897`) ارمِ استثناءً بدل الفتح. ثم هاجِر الشاشاتِ غيرَ المسجَّلةِ إلى `modules` قبل النشر بعلَمِ تفعيلٍ تدريجي. | R12: فريق الباك-إند — الحوكمة والمنصة | S12: نعم | T12: نعم | U12: شاشةٌ غيرُ مسجَّلةٍ في `modules` تُعيد `can_view=false` وتُحجب لكلِّ دورٍ عدا السوبر، ويُكتب حدثُ أمنٍ بكلِّ محاولة. | V12: مفتوح | W12: مؤكَّدة | X12: مؤكَّدٌ سطرًا سطرًا: _default_full_permissions (810-818) تُرجع الأربعَ true، وتُستدعى عند فشل prepare (897-899) وعند عدم العثور على الشاشة (909-911)، والنمطُ نفسُه في get_current_page_permissions (621-629)، والتعليقُ 825 يقرُّ به. والأثرُ حيٌّ: نحوُ ٤٠ شاشةً تضمّن insidebar وليست في modules تُمنح صلاحياتٍ كاملةً لكل مصادَق، والصمّامُ المضادُّ فارغُ البادئات في .env حسب docs/SUPPLIERS_DEPARTMENT_AUDIT_REPORT_ar.md:323. | Y12: P0 | Z12: نعم | AA12: نعم | AB12: 06_M14 | AC12: فجوة تنفيذ (Implementation) | AD12: Decision Closed · Implementation Open
A13: INJ-0009 | B13: M-14 | C13: ▐ ١٠ الحرّاس · الحكمُ الرابع «الحارسُ في الخادم ويُفشَل مغلقًا» | D13: النقل والترحيل | E13: إقفال الأمر وتحميل تكلفته | F13: http://localhost/ems/Transport/transfer_close_cost.php | G13: خامسًا: الإقفال وتحميل التكلفة | H13: الحارسُ في الخادمِ قبل الأثر — ولا يُكتفى بإخفاء الزر؛ ولكلِّ فعلٍ حارسٌ مُثبَتٌ بمُنفِّذه | I13: معالجُ POST في السطر ١٩ ينفّذ UPDATE على transfer_orders و INSERT في transfer_events و transfer_cost_lines قبل السطر ٥٥ الذي يُضمِّن insidebar.php (وفيه الحارسُ الوحيدُ enforce_current_page_view_permission عند insidebar.php:14) — فالأثرُ يقع ثم يُعاد التوجيه؛ ولا فحصَ can_edit ولا رمزَ صلاحيةٍ ولا CSRF | J13: Permission Gap | K13: P0 | L13: أيُّ مستخدمٍ مسجَّلِ الدخولِ — من أيِّ إدارةٍ — يستطيع إقفالَ أمرِ ترحيلٍ وتحميلَ تكلفةٍ فعليةٍ بأيِّ مبلغٍ على مركزِ تكلفة؛ أثرٌ ماليٌّ بلا صلاحية | M13: الشاشةُ من موجة update0007 كُتبت بنمطٍ مختصرٍ (فحصُ الجلسة فقط) ولم تستدعِ trs_page_perms كأخواتها، والحارسُ المركزيُّ يفحص can_view وحدَه ويأتي متأخرًا في ترتيب التضمين | N13: Transport/transfer_close_cost.php:11; Transport/transfer_close_cost.php:19; Transport/transfer_close_cost.php:25; Transport/transfer_close_cost.php:34; Transport/transfer_close_cost.php:55; insidebar.php:14 | P13: ١) ادخل بأيِّ حسابٍ لا يملك صلاحيةَ النقل (مثلًا دور الموارد البشرية). ٢) أرسِل POST إلى /ems/Transport/transfer_close_cost.php بالحقلين close_id=<رقم أمرٍ حالتُه arrived> و actual_cost=999999. ٣) استعلِم transfer_orders: الحالةُ صارت closed و actual_cost_usd=999999. | Q13: في Transport/transfer_close_cost.php أضِف قبل السطر ١٩: require_once trs_helpers.php ثم $perms = trs_page_perms($conn,'Transport/transfer_close_cost.php',$is_super); وارفض بـ403 إن !$perms['can_edit']؛ وأضِف تحققَ رمزِ CSRF، وانقل التحققَ كلَّه قبل أيِّ كتابة | R13: فريق الباك-إند — وحدة النقل والترحيل | S13: نعم | T13: نعم | U13: POST من حسابٍ بلا can_edit على الموديول ٣٠٩ يعيد ٤٠٣ ولا يغيّر صفًّا واحدًا في transfer_orders ولا transfer_cost_lines. | V13: مفتوح | W13: مؤكَّدة | X13: تحققتُ: السطر 19 يفتح معالجَ POST، والسطور 25-28 UPDATE transfer_orders، و30-31 INSERT transfer_events، و33-34 INSERT transfer_cost_lines بمبلغٍ من $_POST — كلُّها قبل include '../insidebar.php' في السطر 55 حيث الحارسُ الوحيد. لا can_edit ولا رمزَ CSRF، ومصفوفةُ الصلاحيات تحصر الموديول 309 بالدور 23 كتابةً — فالأثرُ الماليُّ يقع لأيِّ مصادَق. | Y13: P0 | Z13: نعم | AA13: نعم | AB13: 06_M14 | AC13: فجوة تنفيذ (Implementation) | AD13: Decision Closed · Implementation Open
A14: INJ-0010 | B14: M-14 | C14: ▐ ١٠ الحرّاس · الحكمُ الرابع «الحارسُ في الخادم قبل الأثر» | D14: المشتريات التشغيلية | E14: طلب العروض ومقارنتها (الترسية) | F14: http://localhost/ems/Procurement/rfq_compare_award.php | G14: ثانيًا: العروض والترسية | H14: لا فعلَ يقع قبل حارسٍ خادميٍّ يفحص صلاحيةَ الكتابة؛ والترسيةُ فعلٌ حاكمٌ بأثرٍ تعاقديٍّ ومالي | I14: معالجُ الترسية بلا فحصِ صلاحيةٍ إطلاقًا؛ أمّا CSRF فيغطّيه `ems_enforce_csrf_protection` المركزيُّ في config.php:468 حسب وضعه. — [مُصحَّح بعد التحقق] الصياغة الأولى: معالجُ POST في السطر ٢٠ يُدرج صفَّ ترسيةٍ في rfq_awards (السطر ٣٣) ويحدّث supplier_rfqs إلى 'awarded' (السطر ٣٨) داخل معاملة، وكلُّ ذلك قبل السطر ٦٦ الذي يُضمِّن insidebar.php حيث الحارسُ الوحيدُ (enf | J14: Permission Gap | K14: P0 | L14: أيُّ مستخدمٍ مسجَّلِ الدخولِ في النظام يستطيع ترسيةَ أيِّ طلبِ عروضٍ على أيِّ موردٍ بأيِّ سعر؛ الترسيةُ تُلتزم في القاعدة ثم يُعاد توجيهُ المستخدمِ فقط — أثرٌ تعاقديٌّ كاملٌ بلا صلاحية | M14: شاشةُ الترسيةِ كُتبت بالنمط المختصر (فحصُ الجلسة وحدَه) ولم تستدعِ proc_page_perms كأخواتِها في المجلد نفسِه | N14: Procurement/rfq_compare_award.php:11; Procurement/rfq_compare_award.php:20; Procurement/rfq_compare_award.php:33; Procurement/rfq_compare_award.php:38; Procurement/rfq_compare_award.php:66; insidebar.php:14; Procurement/orders_proc.php:29 | P14: ١) ادخل بحسابٍ من إدارةٍ بلا أيِّ صلة بالمشتريات (مثلًا دور الصيانة). ٢) أرسِل POST إلى /ems/Procurement/rfq_compare_award.php بالحقول award_quote=<معرّف عرض> و award_reason=«اختبار». ٣) استعلِم rfq_awards: صفٌّ جديد؛ واستعلِم supplier_rfqs: state='awarded'. | Q14: في Procurement/rfq_compare_award.php أضِف قبل السطر ٢٠: require_once __DIR__.'/proc_helpers.php'; $ctx=proc_ctx(); $perms=proc_page_perms($conn,'Procurement/rfq_compare_award.php',$ctx['is_super']); if(!$perms['can_edit']) { ems_gov_flash_redirect('rfq_compare_award.php','لا صلاحية ترسية ❌','GOV-PERM-403',''); exit(); } وأضِف تحققَ رمز CSRF | R14: فريق الباك-إند — وحدة المشتريات | S14: نعم | T14: نعم | U14: POST من حسابٍ بلا can_edit على الموديول ٢٩٨ يعيد ٤٠٣ ولا يُدرج صفًّا في rfq_awards ولا يغيّر supplier_rfqs. | V14: مفتوح | W14: مؤكَّدة | X14: محقَّقٌ بالكامل: Procurement/rfq_compare_award.php:20 يفتح معالجَ الترسية، و:33 يدرج صفًّا في rfq_awards و:38 يحوّل supplier_rfqs إلى 'awarded' داخل معاملة، وinsidebar في السطر 66 بعد ذلك كلِّه — بلا can_add/can_edit ولا رمزِ فعل؛ وأثرُه ترسيةُ عطاءٍ على موردٍ (أثرٌ ماليٌّ وقانونيٌّ) يقفلُه فحصُ التكرار فلا يُرسى البندُ ثانيةً. (ملاحظة: CSRF محروسٌ مركزيًّا في config.php لا في الشاشة، فالجزءُ الخاصُّ به من الادّعاء غيرُ دقيق.) | Y14: P0 | Z14: نعم | AA14: نعم | AB14: 06_M14 | AC14: فجوة تنفيذ (Implementation) | AD14: Decision Closed · Implementation Open
A15: INJ-0011 | B15: M-14 | C15: ▐ ١٠ الحرّاس · الحكمُ الرابع «الحارسُ في الخادم قبل الأثر» | D15: المخازن | E15: التحويل بين المخازن | F15: http://localhost/ems/Procurement/wh_transfer.php | G15: ثانيًا: الإدخال والرصيد | H15: لا فعلَ يقع قبل حارسٍ خادميٍّ يفحص صلاحيةَ الكتابة — والرصيدُ أثرٌ مادّيٌّ لا يُمسّ بلا صلاحية | I15: معالجُ POST في السطر ١٨ يفتح معاملةً ويُدرج حركتَي مخزونٍ (تحويل صادر/وارد) في السطرين ٣٤ و٣٦ قبل السطر ٦٠ الذي يُضمِّن insidebar.php حيث الحارسُ الوحيدُ (can_view فقط، insidebar.php:14)؛ ولا فحصَ can_edit ولا رمزَ CSRF — رغم أن مصفوفةَ الصلاحيات تحصر الموديول ٣٠١ بدور «أمين المستودع» وحدَه | J15: Permission Gap | K15: P0 | L15: أيُّ مستخدمٍ مسجَّلٍ في النظام يستطيع نقلَ أيِّ كميةٍ من أيِّ صنفٍ بين أيِّ مخزنين؛ ورصيدُ المخزون محسوبٌ من هذه الحركات، فالأثرُ مباشرٌ على قيمةِ المخزون وعلى تكلفةِ ما يُصرَف منه | M15: شاشةٌ من موجة update0007 كُتبت بالنمط المختصر (فحصُ الجلسة وحدَه) ولم تستدعِ proc_page_perms كأخواتها في المجلد نفسِه | N15: Procurement/wh_transfer.php:10; Procurement/wh_transfer.php:18; Procurement/wh_transfer.php:34; Procurement/wh_transfer.php:36; Procurement/wh_transfer.php:60; insidebar.php:14; database/schema/seed_reference.sql:349; database/schema/seed_reference.sql:1969 | P15: ١) ادخل بحسابٍ من إدارةٍ لا علاقةَ لها بالمخازن. ٢) أرسِل POST إلى /ems/Procurement/wh_transfer.php بالحقول item_id و from_wh و to_wh و qty. ٣) استعلِم proc_stock_move: حركتان جديدتان بمرجع TRF. | Q15: في Procurement/wh_transfer.php أضِف قبل السطر ١٨: $ctx=proc_ctx(); $perms=proc_page_perms($conn,'Procurement/wh_transfer.php',$ctx['is_super']); if(!$perms['can_edit']) { ems_gov_flash_redirect('wh_transfer.php','لا صلاحية تحويل ❌','GOV-PERM-403',''); exit(); } مع تحققِ رمز CSRF | R15: فريق الباك-إند — وحدة المخازن | S15: نعم | T15: نعم | U15: POST من حسابٍ بلا can_edit على الموديول ٣٠١ يعيد ٤٠٣ ولا يُدرج أيَّ صفٍّ في proc_stock_move. | V15: مفتوح | W15: مؤكَّدة | X15: تحققتُ: السطر 18 معالجُ POST، والسطور 32-37 تفتح معاملةً وتُدرج حركتَي proc_stock_move (تحويل صادر/وارد) قبل include '../insidebar.php' في السطر 60. لا فحصَ can_edit ولا رمزَ CSRF، ومصفوفةُ الصلاحيات تحصر الموديول 301 بالدور 25 وحدَه (seed_reference.sql:349,1969) — فأيُّ مصادَقٍ يحرّك رصيدَ المخازن. | Y15: P0 | Z15: نعم | AA15: نعم | AB15: 06_M14 | AC15: فجوة تنفيذ (Implementation) | AD15: Decision Closed · Implementation Open
A16: INJ-0012 | B16: M-14 | C16: ▐ ١٠ الحرّاس · «الحارسُ لا يثق بمدخلات العميل» | D16: المخازن | E16: الجرد ومعالجة الفروقات | F16: http://localhost/ems/Procurement/wh_count.php | G16: رابعًا: الجرد والرقابة | H16: «رابعًا: الجرد والرقابة | محضر جرد · قيد تسوية | المعتمِد: مدير المخازن» — والحارسُ في الخادم ولا يُحتسب فرقٌ من قيمةٍ يرسلها المتصفح | I16: الشاشةُ بلا أيِّ حارسِ صلاحيةٍ (فحصُ الجلسة وحدَه في السطر ١٠، والحارسُ المركزيُّ يأتي في السطر ٥٦ بعد الكتابة)، والأخطرُ أن «الرصيدَ الدفتري» يُرسَل من المتصفح في حقلٍ مخفيٍّ book_qty ويُحسب الفرقُ منه في الخادم ($diff = $actual - $book) بلا إعادةِ احتسابِ الرصيد من proc_stock_move — فالمهاجمُ يتحكم بطرفَي المعادلة | J16: Permission Gap | K16: P0 | L16: أيُّ مستخدمٍ مسجَّلٍ يستطيع كتابةَ تسويةِ مخزونٍ بأيِّ مقدارٍ (زيادةً أو عجزًا) بإرسال book_qty=0 و actual_qty=1000 — أي إنشاءَ مخزونٍ من العدم أو إخفاءَ عجزٍ، بسببٍ نصيٍّ حرٍّ وبلا معتمِدٍ ولا محضرِ جرد | M16: حسابُ الفرق مبنيٌّ على قيمةٍ من العميل، والشاشةُ بلا حارسٍ خادميٍّ ولا اعتمادٍ من مدير المخازن | N16: Procurement/wh_count.php:10; Procurement/wh_count.php:19; Procurement/wh_count.php:22; Procurement/wh_count.php:24; Procurement/wh_count.php:29; Procurement/wh_count.php:116; Procurement/wh_count.php:56 | P16: ١) ادخل بأيِّ حسابٍ مسجَّل. ٢) أرسِل POST إلى /ems/Procurement/wh_count.php?wh=1 بالحقول adjust_item=<صنف> و book_qty=0 و actual_qty=1000 و reason=«جرد». ٣) استعلِم proc_stock_move: حركةُ «تسوية زيادة» بكمية ١٠٠٠. | Q16: في Procurement/wh_count.php: (أ) أضِف حارسَ proc_page_perms + can_edit قبل معالج POST؛ (ب) احذف الحقلَ المخفي book_qty وأعِد احتسابَ الرصيد الدفتري في الخادم من proc_stock_move داخل المعاملة؛ (ج) اشترِط اعتمادَ دورِ مدير المخازن قبل كتابة حركة التسوية | R16: فريق الباك-إند — وحدة المخازن | S16: نعم | T16: نعم | U16: POST بقيمة book_qty ملفَّقةٍ يُنتج حركةَ تسويةٍ محسوبةً من الرصيد الحقيقيِّ لا من المُدخَل، ويُرفض كليًّا بلا can_edit وبلا اعتماد مدير المخازن. | V16: مفتوح | W16: مؤكَّدة | X16: محقَّقٌ بالسطر: Procurement/wh_count.php بلا أيِّ فحصِ صلاحية (الجلسةُ وحدَها في السطر 10) والحارسُ المركزيُّ في السطر 56 بعد الكتابة، ومعالجُ السطر 19-32 يحسب `$diff = $actual - $book` من `book_qty` القادمِ في حقلٍ مخفيٍّ من المتصفح ثم يدرج حركةَ «تسوية زيادة/عجز» في `proc_stock_move` — وهو دفترُ الأرصدة الذي يُحسب منه الرصيدُ الدفتريُّ نفسُه (السطر 40-45)، فالمهاجمُ يتحكم بمقدار التسوية بالكامل. | Y16: P0 | Z16: نعم | AA16: نعم | AB16: 06_M14 | AC16: فجوة تنفيذ (Implementation) | AD16: Decision Closed · Implementation Open
A17: INJ-0013 | B17: INJAZ-FRD-01 | C17: §١٢-٣ المرحلة ٤ · «متحقِّقٌ مستقل» — لا مرحلةَ بلا مخرَج | D17: المراجع الداخلي المستقل | E17: ميثاق المراجعة الداخلية / الكون الرقابي / خطة المراجعة / مهام المراجعة | F17: http://localhost/ems/Audit/iaf_charter.php | G17: غير موجود في السايدبار | H17: «لا مهمةَ بلا خطةٍ ولا خطةَ بلا كونٍ رقابيٍّ ولا كونَ بلا ميثاق» (IAF-0044) — ولكلِّ مرحلةٍ مستندٌ يُنتَج ومعتمِدٌ يشهد. | I17: من الشاشاتِ الستَّ عشرةَ في `Audit/` **شاشةٌ واحدةٌ فقط** تحمل كتلةَ `actions` هي `Audit/iaf_findings.php:32-55` (قبولُ دليلٍ وإغلاقُ ملاحظة). أمّا `iaf_charter` و`iaf_universe` و`iaf_plan` و`iaf_engagements` و`iaf_workpapers` و`iaf_independence` وسائرُها فبلا أيِّ فعل — فلا سبيلَ لإنشاءِ ميثاقٍ ولا اعتمادِه ولا بناءِ كونٍ رقابيٍّ ولا خطةٍ ولا مهمةٍ ولا ورقةِ عملٍ ولا حتى **رفعِ ملاحظة**. والدالةُ `assertCycle` (`InternalAuditService.php:99`) بلا نداءات. | J17: Missing Screen | K17: P0 | L17: دورةُ المراجعةِ الداخليةِ كاملةً غيرُ قابلةٍ للبدء: لا ميثاقَ يُعتمد فلا كونَ فلا خطةَ فلا مهمةَ فلا ملاحظة — والشاشتانِ الوحيدتانِ ذواتا الأفعال (`iaf_findings`) تعملان على صفوفٍ لا يمكن إنشاؤها. النتيجةُ ستَّ عشرةَ شاشةً تعرض «لا بيانات» إلى الأبد. | M17: وُلِّدت الشاشاتُ من بيانِ `tools/u13_screens_manifest.php` بعقودِ عرضٍ فقط؛ ولم تُكتب عقودُ الأفعالِ إلا لشاشةٍ واحدة. | N17: Audit/iaf_charter.php:19; :30; Audit/iaf_universe.php:19; Audit/iaf_plan.php:19; Audit/iaf_engagements.php:19; Audit/iaf_findings.php:32; :55; app/Services/Audit/InternalAuditService.php:99; includes/u13_screen_kit.php:145; :254 | P17: ١) بحساب دور 33 افتح `Audit/iaf_charter.php`: لا كتلةَ «الأفعالُ المتاحةُ على هذه الشاشة» لأن `$U13['actions']` غيرُ معرَّفة. ٢) كرِّر على `iaf_universe` و`iaf_plan` و`iaf_engagements`: النتيجةُ نفسُها. ٣) افتح `Audit/iaf_findings.php`: فعلانِ فقط، وكلاهما يفترض ملاحظةً قائمةً لا سبيلَ لإنشائها. | Q17: أضِف في `tools/u13_screens_manifest.php` عقودَ الأفعالِ الناقصةَ وأعِد التوليد: `iaf.charter.approve` · `iaf.universe.build` · `iaf.plan.approve` · `iaf.engagement.open` · `iaf.workpaper.attach` · `iaf.finding.raise` · `iaf.response.submit` · `iaf.actionplan.set`؛ ونفِّذ كلَّ فعلٍ عبر `InternalAuditService` مع نداءِ `assertCycle` قبله. | R17: فريق الباك-إند — وحدة المراجعة الداخلية (IAF-01) | S17: نعم | T17: نعم | U17: بحساب دور 33: اعتمِد ميثاقًا ← ابنِ كونًا ← اعتمِد خطةً ← افتح مهمةً ← ارفع ملاحظةً ← اقبل دليلًا ← أغلِق — السلسلةُ السبعُ تعمل من الشاشات، وكلُّ قفزةٍ في الترتيبِ تُرفض بـIAF-0044. | V17: مفتوح | W17: مؤكَّدة | X17: تحققتُ بالجرد: من الستَّ عشرةَ شاشةً في Audit/ شاشةٌ واحدةٌ فقط (iaf_findings.php:32-55) تعلن كتلةَ actions، و includes/u13_screen_kit.php:145,254 لا يصيّر أفعالًا إلا للمعلَنة ولا يقدّم نموذجَ إنشاءٍ عامًّا، و assertCycle بلا نداءٍ خارجَ tools/u13_gate.php. فلا ميثاقَ يُنشأ ولا كونَ ولا خطةَ ولا مهمةَ ولا ملاحظةَ تُرفع — والفعلان الوحيدان يعملان على صفوفٍ لا تُنشأ. | Y17: P0 | Z17: نعم | AA17: نعم | AB17: 02_FRD | AC17: فجوة تنفيذ (Implementation) | AD17: Decision Closed · Implementation Open
A18: INJ-0014 | B18: INJAZ-FRD-01 | C18: INJAZ-FRD-01 §٢-٢ · الأحكامُ التي لا تُخالَف | D18: مكتب الرئيس التنفيذي والنواب | E18: توقيع العقود والالتزامات | F18: http://localhost/ems/Portal/ceo_contracts.php | G18: ثالثًا: توقيع العقود | H18: «◆ لا يُثبَّت الرئيسُ التنفيذيُّ معتمِدًا لكل عقدٍ — بل المخوَّلُ ضمن سقفِه ويُصعَّد عند التجاوز.» و«نموذجُ القيادةِ الأحدثُ يقوم على الرئيس التنفيذيِّ وثلاثةِ نوابٍ بنطاقٍ وسقفٍ وتفويضٍ لكلٍّ … وإنابتُه». | I18: التوقيعُ والاعتمادُ وفتحُ المشروع كلُّها محروسةٌ بمقارنةٍ نصيةٍ صلبةٍ واحدة: `$actorRole !== '9'` — لا سقفَ مبلغٍ يُقاس، ولا جدولَ `signing_authorities` يُستشار، ولا نائبَ ولا مُناب. و`exec_dept_caps` تُقرأ في بوابة الطلب المالي فقط لا عند التوقيع. | J18: Governance Gap | K18: P1 | L18: نموذجُ «الرئيس ونوابُه الثلاثة» غيرُ منفَّذٍ إطلاقًا: لا يستطيع نائبٌ توقيعَ عقدٍ في نطاقه، ويستطيع أيُّ حاملٍ للدور 9 توقيعَ عقدٍ بأيِّ مبلغٍ بلا سقف. وتوقُّفُ التوقيع على حسابٍ واحدٍ يجمّد التعاقدَ عند غيابه. | M18: تمثيلُ السلطةِ برقمِ دورٍ واحدٍ بدل مصفوفةِ (نطاق × سقف × تفويض)؛ و`app/Core/AuthorityGuard.php::sign()` القائمُ لا يُستدعى من أيِّ شاشةٍ من شاشات القمة. | N18: Portal/ceo_contracts.php:131; :138; :180-185; Portal/ceo_approvals.php:114; Portal/project_charter.php:148; Governance/signing_authority.php:23; Governance/signing_authority.php:63 | P18: ١) ادخل بحساب نائبٍ (أي دورٍ غير 9) له can_edit على Portal/ceo_contracts.php. ٢) افتح الشاشة ولاحظ اختفاءَ لوحة التوقيع. ٣) أرسل POST بـ cmp03_action=sign ⇒ رفضٌ بـ GOV-PERM-403 مهما كان مبلغُ العقد. ٤) ادخل بدور 9 ووقّع عقدًا بمبلغٍ خرافي ⇒ يُقبل بلا سقف. | Q18: في `Portal/ceo_contracts.php` استبدل شرطَ الدور بمستدعٍ لـ`App\Core\AuthorityGuard::sign()` يقرأ `signing_authorities` (النطاق · السقف · التفويض · مدة الإنابة) ويقارن `amount` بسقف الموقِّع؛ وسجّل `authority_ref` من صفِّ التفويض لا من نصٍّ حر. طبّق النمطَ نفسَه في ceo_approvals.php:114 و project_charter.php:148. | R18: فريق الباك-إند — وحدة الحوكمة والصلاحيات | S18: نعم | T18: نعم | U18: نائبٌ بسقف 100,000 يوقّع عقدًا بـ 90,000 ⇒ يُقبل ويُسجَّل مرجعُ تفويضه؛ ويوقّع عقدًا بـ 150,000 ⇒ يُرفض ويُصعَّد تلقائيًّا لصندوق الرئيس. | V18: مفتوح | W18: مؤكَّدة | X18: تحققتُ من الأسطر: ceo_contracts.php:131 و ceo_approvals.php:114 و project_charter.php:148 كلُّها شرطٌ نصيٌّ واحد $actorRole !== '9' بلا قياسِ سقفٍ ولا قراءةِ signing_authorities. و AuthorityGuard::sign يُستدعى إنتاجيًّا من خدماتٍ أخرى لكن لا من شاشات القمة، وexec_dept_caps تُقرأ في FinRequests/_finreq_helpers.php:879 وحدَها. | Y18: P1 | Z18: نعم | AA18: نعم | AB18: 01_CORE | AC18: فجوة تنفيذ (Implementation) | AD18: Decision Closed · Implementation Open
A19: INJ-0015 | B19: INJAZ-FRD-01 | C19: INJAZ-FRD-01 §٤-٥ · المستهلكُ في عقد الفعل السداسي | D19: مكتب الرئيس التنفيذي والنواب | E19: اعتمادات المدير التنفيذي | F19: http://localhost/ems/Portal/ceo_approvals.php | G19: ثانيًا: الاعتمادات العليا | H19: عقدُ كلِّ فعلٍ سداسيٌّ يحدّد «المستهلكَ» — والإداراتُ المتأثرةُ بأفعال القمة تسعٌ: المالية والخزينة · المبيعات والعقود · إدارة الموردين · التمويل والملكية · الموارد البشرية · إدارة التشغيل · الحوكمة والالتزام · إدارة الأسطول · إدارة المخاطر. | I19: التصحيح: `ems_business_events` **يُقرأ** فعلًا (WorkspaceFeedService.php:206 · Portal/ceo_reports.php) لكنها قراءاتُ عرضٍ لا مستهلكٌ يغلق الحلقة. — [مُصحَّح بعد التحقق] الصياغة الأولى: لا مستهلكَ واحدًا لأيٍّ من مفاتيح القمة الأربعة: البحثُ في المستودع عن `exec.approval.granted` يعيد ناشرَين وقارئَي عدٍّ في لوحةٍ وتقرير؛ ولا مستهلكَ يقرأ من `ems_business_events` أصلًا. فالطلبُ المال | J19: Event/Integration Gap | K19: P1 | L19: حلقةُ التصعيد مفتوحةٌ من طرف: الطلبُ يُرفع آليًّا إلى صندوق القمة (BR-CEO-05) لكنّ نتيجةَ الاعتماد لا ترجع إلى الطلب الأصلي — فتبقى الطلباتُ عالقةً في «قيد الاعتماد» في بوابة الطلبات المالية بعد بتِّها فعليًّا. | M19: تصميمُ الجسر أحاديُّ الاتجاه: `finreq_gm_escalate()` يكتب في exec_approvals ويحمل `source_request_id`، ولا يوجد ما يقرأ هذا العمودَ عند البتّ. | N19: FinRequests/_finreq_helpers.php:938; FinRequests/_finreq_helpers.php:964; FinRequests/_finreq_helpers.php:986-995; Portal/ceo_approvals.php:170-197; Portal/ceo_reports.php:60 | P19: ١) أنشئ طلبًا ماليًّا يتجاوز سقفَ الإدارة ⇒ يُرفع صفٌّ إلى exec_approvals ويصل تنبيهٌ للتنفيذي. ٢) اعتمده من Portal/ceo_approvals.php. ٣) افتح FinRequests/my_requests.php ⇒ الطلبُ ما زال في حالته السابقة بلا أثرٍ للاعتماد. | Q19: في `Portal/ceo_approvals.php` بعد نجاح فرع decide: إن كان `$row['source_request_id'] > 0` فحدِّث الطلبَ الأصليَّ عبر خدمةِ الطلبات (تمريرُ القرار والسبب) وأصدِر إشعارًا لمنشئه؛ والأصحُّ معماريًّا: أنشئ مستهلكًا لـ`exec.approval.granted` في `app/Services/Work/RequestService.php` يفعل ذلك بمفتاح عطالة. | R19: فريق الباك-إند — وحدة الطلبات المالية | S19: نعم | T19: لا | U19: اعتمادُ صفٍّ مرفوعٍ من طلبٍ مالي ينقل الطلبَ الأصليَّ إلى الحالة التالية ويصل إشعارٌ لمنشئه خلال دورةٍ واحدة. | V19: مفتوح | W19: مؤكَّدة | X19: تحقّقت: قرارُ ceo_approvals لا يمسّ `source_request_id` ولا يحدّث الطلبَ المصدري، و`publishFact` يكتب في الجذر المحايد وحدَه بينما EventDispatcher يستهلك من `fin_financial_events` — فلا مستهلكَ لـexec.approval.granted. | Y19: P1 | Z19: نعم | AA19: نعم | AB19: 02_FRD | AC19: فجوة تنفيذ (Implementation) | AD19: Decision Closed · Implementation Open
A20: INJ-0016 | B20: M-14 | C20: SEC-015-ب · فصلُ الواجبات — الزوجُ ⑥ إنشاءُ الصلاحيةِ واعتمادُها | D20: مكتب الرئيس التنفيذي والنواب | E20: اعتمادات المدير التنفيذي | F20: http://localhost/ems/Portal/ceo_approvals.php | G20: ثانيًا: الاعتمادات العليا | H20: «لا يعتمد المرءُ ما أعدّ» — والاعتمادُ الأعلى فعلٌ محجوزٌ للإدارة التنفيذية بسلطتها أو بتفويضٍ موثَّق، ويُسجَّل المعتمِدُ بصفته ومرجعِ تفويضه. | I20: مسارُ «إضافة» (cmp03_action=add) يقبل الحقولَ f12..f16 (قراري · سبب القرار · تاريخ القرار · المعتمِد — الاسم والصفة · مرجع التفويض) وحقلَ الحالة f17 الذي تتضمن قائمتُه القيمةَ «معتمد»، ويُدرجها مباشرةً في `exec_approvals` بحارسٍ واحدٍ هو can_add/can_edit على الشاشة — بلا أيِّ فحصٍ للدور 9. فأيُّ مستخدمٍ يملك can_add يفبرك اعتمادًا أعلى كاملَ الحقول بحالة «معتمد». | J20: Permission Gap | K20: P1 | L20: تُلتفّ حراسةُ الدور 9 الموضوعةُ على مسار «القرار» بالكامل: يظهر في سجل الاعتمادات العليا صفٌّ «معتمد» باسم معتمِدٍ ومرجعِ تفويضٍ يكتبهما المُدخِلُ بيده، ويُقرأ لاحقًا سندًا لصرفٍ أو تعاقدٍ تجاوز السقف. | M20: حارسان مختلفان لمسارين يكتبان الأعمدةَ نفسَها: مسارُ القرار محروسٌ بالدور (سطر 114) ومسارُ الإضافة محروسٌ بصلاحية CRUD فقط (سطر 37)، وقادحُ القاعدة BR-CEO-08 يمنع تعديلَ المقرَّر لا إنشاءَه مقرَّرًا. | N20: Portal/ceo_approvals.php:37; :76; :63-68; :87; :99; :114; :294 | P20: ١) امنح دورًا غيرَ 9 صلاحيةَ can_add على Portal/ceo_approvals.php. ٢) ادخل بذلك الدور وافتح الشاشة. ٣) اضغط «إضافة» واملأ «قراري=اعتماد» و«المعتمِد — الاسم والصفة» و«مرجع التفويض» واختر الحالة «معتمد». ٤) احفظ. ٥) لاحظ ظهور الصف معتمدًا في الجدول بلا مرور الدور 9. | Q20: في `Portal/ceo_approvals.php` داخل فرع add (سطر 76): امنع كتابةَ الحقول decision · decision_reason · decision_date · approver_name · authority_ref و status='معتمد' إلا إذا كان `$actorRole==='9'`؛ واجعل الإدراجَ يفرض status='مسودة' و decision=NULL دائمًا للمُدخِل غير التنفيذي، وأزِل «معتمد» من قائمة f17. | R20: فريق الباك-إند — وحدة القمة التنفيذية (Portal) | S20: نعم | T20: نعم | U20: مستخدمٌ بدور غير 9 وله can_add يحفظ صفًّا بحالة «معتمد» ⇒ يجب أن يُرفض برسالة GOV-PERM-403 وأن يبقى الصفُّ «مسودة» بأعمدة القرار فارغة. | V20: مفتوح | W20: مؤكَّدة | X20: فرعُ add في Portal/ceo_approvals.php:76 يُدرج decision/approver_name/authority_ref وstatus='معتمد' (خيارٌ في القائمة سطر 294) بحارس can_add/can_edit وحده (سطر 37)، بينما فرعُ decide وحدَه يفحص الدور 9 (سطر 114)؛ وقادحُ BR-CEO-08 في هجرة 2026_11_14 قبلَ UPDATE لا INSERT فلا يمنع الإنشاءَ مقرَّرًا. | Y20: P1 | Z20: نعم | AA20: نعم | AB20: 06_M14 | AC20: فجوة تنفيذ (Implementation) | AD20: Decision Closed · Implementation Open
A21: INJ-0017 | B21: M-14 | C21: GOV-009-ب · حارسُ منعِ اعتمادِ الذات على كلِّ موافقة | D21: مكتب الرئيس التنفيذي والنواب | E21: اعتمادات المدير التنفيذي | F21: http://localhost/ems/Portal/ceo_approvals.php | G21: ثانيًا: الاعتمادات العليا | H21: «حارسُ منعِ اعتمادِ الذات» يُستدعى على كلِّ نقطةِ اعتماد: من أنشأ المستندَ لا يعتمده — ويُقارَن المعتمِدُ بمنشئِ الصفِّ لحظةَ المعاملة لا عند منحِ الدور. | I21: لا استدعاءَ لـ`ems_no_self_approval()` في الملف كلِّه؛ فرعُ القرار (سطر 111) يقرأ الصفَّ ويحدّث أعمدةَ القرار بلا مقارنةٍ بين `created_by` و`$uid`. والدورُ 9 نفسُه يستطيع إنشاءَ الصفِّ ثم بتَّه في الجلسة نفسِها. | J21: Permission Gap | K21: P1 | L21: أعلى نقطةِ اعتمادٍ ماليٍّ في المنظومة (ما تجاوز سقوفَ الإدارات) بلا فصلِ يدين: التنفيذيُّ يرفع ويعتمد بنفسه، فيسقط الشاهدُ الرقابيُّ الوحيد على تجاوز السقوف. | M21: الحارسُ `includes/self_approval_guard.php:22` قائمٌ ومستعمَلٌ في أربع نقاطٍ فقط، ولم يُزرع في شاشات القمة؛ والحراسةُ هنا رايةُ دورٍ لا فحصُ يد. | N21: Portal/ceo_approvals.php:111; :127; :154; :165; includes/self_approval_guard.php:22; Contracts/claims.php:99 | P21: ١) ادخل بدور 9. ٢) أضِف صفًّا جديدًا في اعتمادات المدير التنفيذي (سيُسجَّل created_by باسمك). ٣) من لوحة القرار الرباعي اختر الصفَّ نفسَه واضغط «قيد القرار» بخيار «اعتماد». ٤) لاحظ نجاحَ الاعتماد بلا أيِّ منع. | Q21: في `Portal/ceo_approvals.php` قبل تنفيذ UPDATE في فرع decide (بعد سطر 134): `require_once includes/self_approval_guard.php;` ثم `$sa = ems_no_self_approval($conn, intval($row['created_by']), $uid, 'EXAP-'.$rowId, $company_id); if ($sa!==null) { $goBack($sa['reason']); }`. | R21: فريق الباك-إند — وحدة القمة التنفيذية (Portal) | S21: نعم | T21: لا | U21: مستخدمٌ أنشأ صفَّ اعتمادٍ ثم حاول بتَّه ⇒ يُرفض برسالة «لا يعتمد المرءُ ما أعدّ»، ومستخدمٌ آخرُ بدور 9 يبتُّه بنجاح. | V21: مفتوح | W21: مؤكَّدة | X21: تحقّقتُ: لا استدعاءَ لـems_no_self_approval في Portal/ceo_approvals.php، وفرعُ القرار (سطر 111) يحدّث exec_approvals بعد فحصِ الدور 9 فقط بلا مقارنةٍ بـcreated_by الموجودِ فعلًا في الجدول. والحارسُ مستعملٌ في أربع نقاطٍ إنتاجيةٍ أخرى فقط. | Y21: P1 | Z21: نعم | AA21: نعم | AB21: 06_M14 | AC21: فجوة تنفيذ (Implementation) | AD21: Decision Closed · Implementation Open
A22: INJ-0018 | B22: INJAZ-FRD-01 | C22: INJAZ-FRD-01 §٤-٣ · BR-CEO-03 — لا فتحَ مشروعٍ بقرارٍ فردي | D22: مكتب الرئيس التنفيذي والنواب | E22: قرار فتح مشروع جديد | F22: http://localhost/ems/Portal/project_charter.php | G22: رابعًا: فتح المشاريع | H22: «المشروعُ يُفتح بمركز تكلفته · ومديرُ الموقع يُعيَّن بصلاحياته · والمواقعُ تُنشأ · والموارد تُحجز — ولا يقع شيءٌ من هذا بقرارٍ فردي» — والإفادةُ رأيٌ ملزمٌ للعرض. | I22: الإفاداتُ الخمسُ (التشغيل · المبيعات · القوى · المالية · الأسطول) خمسةُ حقولِ نصٍّ حرٍّ في الفورم نفسِه يملؤها المستخدمُ الذي يعتمد؛ ولا صفَّ إفادةٍ منفصلٌ بمُفيدٍ وتاريخٍ ومستند، ولا فحصَ أن المُفيدَ ينتمي للإدارة المعنيّة. الشرطُ الوحيدُ أن الحقلَ غيرُ فارغ. | J22: Governance Gap | K22: P1 | L22: حكمُ «لا قرارَ فرديّ» يتحول إلى شرطِ ملءِ خمسِ خانات: يستطيع الدورُ 9 كتابةَ «تمت» في الخمسة واعتمادَ الفتح خلال دقيقة، فيُفتح مشروعٌ بمركزِ تكلفةٍ وموارد بلا موافقةِ إدارةٍ واحدةٍ فعلية. | M22: نمذجةُ الإفادةِ حقلًا نصيًّا في مستند القرار بدل كيانٍ مستقلٍّ (إفادة = مُفيد + إدارة + تاريخ + مستند + حالة) مربوطٍ بصندوق موافقات الإدارة. | N22: Portal/project_charter.php:83-89; :101-112; :166-172; :75 | P22: ١) ادخل بدور 9. ٢) أضِف قرارَ فتحٍ واكتب «تمت» في الحقول الخمسة للإفادات. ٣) اضغط «اعتماد الفتح» ⇒ ينجح فورًا. ٤) ابحث عن أيِّ سجلِّ إفادةٍ في القاعدة ⇒ لا جدولَ ولا صف. | Q22: أنشئ جدول `charter_certifications(charter_id, dept_code, certified_by, certified_at, doc_ref, state)` وحوّل الحقولَ الخمسةَ في `Portal/project_charter.php` إلى قراءةٍ منه؛ واجعل فرعَ charter (سطر 166) يفحص وجودَ خمسِ صفوفٍ بحالة «معتمد» ومُفيدٍ من الإدارة نفسِها. | R22: فريق الباك-إند — وحدة القمة التنفيذية (Portal) | S22: نعم | T22: نعم | U22: محاولةُ اعتماد الفتح مع إفادةٍ واحدةٍ ناقصةٍ أو مكتوبةٍ من غير إدارتها ⇒ رفضٌ يسمّي الإدارةَ الناقصة؛ ولا يُقبل نصٌّ حرٌّ بديلًا عن صفِّ إفادة. | V22: مفتوح | W22: مؤكَّدة | X22: الإفاداتُ الخمسُ حقولُ نصٍّ حرٍّ في الفورم نفسِه ويكفي أن تكون غيرَ فارغةٍ في فرعَي الإضافة والاعتماد؛ ولا جدولَ إفاداتٍ ولا فحصَ انتماءِ المُفيدِ لإدارته، والوثيقةُ تجعل معتمِدَ المرحلة «القرارَ المشترك». | Y22: P1 | Z22: نعم | AA22: نعم | AB22: 06_M14 | AC22: فجوة تنفيذ (Implementation) | AD22: Decision Closed · Implementation Open
A23: INJ-0019 | B23: INJAZ-FRD-01 | C23: INJAZ-FRD-01 §٥ · إدارةُ التشغيل — إسنادُ التوقفات وأثرُه العابر | D23: إدارة التشغيل | E23: التوقفات وتحديد المتحمل | F23: http://localhost/ems/Operations/stops_unattributed.php | G23: ثالثًا: اعتماد الوحدات | H23: من مِلك إدارة التشغيل: «إسنادَ التوقفات» — والأثرُ ينتقل إلى المبيعات (خصمٌ في المطالبة) وإلى الموردين (تحميلٌ وجزاء) وإلى الصيانة، بالأحداث لا بالنداء. | I23: القيمةُ تُكتب في العمود `timesheet.fault_department` ثم لا يقرؤها أحد: مسحُ المستودع كلِّه يُظهر أن العمودَ يُقرأ للعرض فقط في شاشتَي الاعتماد والتايم شيت؛ ولا مطالبةٌ ولا جزاءٌ ولا تسويةُ موردٍ ولا قاعدةُ تحميلٍ تستعمله، ولا يُنشر حدثٌ عند الإسناد. | J23: Event/Integration Gap | K23: P1 | L23: أهمُّ قرارٍ تشغيليٍّ ذي أثرٍ مالي (من يتحمل ساعةَ التعطل) لا يصل أيَّ إدارةٍ أخرى: المطالباتُ تُحتسب بلا خصم، وتسوياتُ الموردين بلا تحميل، فيضيع الأثرُ المالي كاملًا ويُعاد احتسابُه يدويًّا خارج النظام. | M23: نمذجةُ التبعة عمودًا نصيًّا في جدول التايم شيت بدل واقعةٍ (stop event) لها ذمّةٌ ومستهلكون، وغيابُ أيِّ نشرٍ عند الإسناد. | N23: Operations/stops_unattributed.php:22; Timesheet/view_timesheet.php:289; Approvals/hours_approval.php:320; Contracts/penalties.php:1; app/Services/Contract/PenaltyService.php:1 | P23: ١) أسنِد توقفًا إلى «المورد». ٢) افتح Suppliers/settlements.php وولّد تسويةً للمورد نفسِه للفترة ⇒ لا بندَ تحميلٍ للتوقف. ٣) افتح Contracts/penalties.php واحتسب ⇒ لا خصمَ مرتبطٌ بالتوقف. | Q23: بعد نجاح الإسناد في `Operations/stops_unattributed.php` انشر `operations.stop.attributed` بـ`publishFact` (الجهة · الساعات · العقد · الفترة · مفتاح عطالة ts:<id>)، وأضِف مستهلكَين: أحدهما في `app/Services/Contract/PenaltyService::assess` والآخر في `app/Services/Settlement/SettlementService::generate` يقرآن الواقعةَ ويولّدان البندَ. | R23: فريق الباك-إند — وحدة التشغيل | S23: نعم | T23: لا | U23: إسنادُ توقفٍ إلى مورد ثم توليدُ تسويته للفترة يُنتج بندَ تحميلٍ بمرجع التوقف؛ وإسنادُه إلى العميل يُنتج بندَ خصمٍ في مستخلص الفترة. | V23: مفتوح | W23: مؤكَّدة | X23: الإسنادُ يكتب timesheet.fault_department في stops_unattributed.php:22، ومسحُ المستودع يُظهر قراءةً للعرض فقط في hours_approval.php:320 و view_timesheet.php:289 و api/controllers/timesheet.php:368 — لا مطالبةَ ولا جزاءَ ولا تسويةَ تقرؤه ولا حدثَ يُنشر. والخدمتان المذكورتان في الإصلاح قائمتان فعلًا. | Y23: P1 | Z23: نعم | AA23: نعم | AB23: 02_FRD | AC23: فجوة تنفيذ (Implementation) | AD23: Decision Closed · Implementation Open
A24: INJ-0020 | B24: INJAZ-FRD-01 | C24: INJAZ-FRD-01 §٥-٣ · المرحلة ٥ — الإقفالُ الشهري | D24: إدارة التشغيل | E24: الإقفال الشهري للوحدة | F24: http://localhost/ems/Operations/monthly_close.php | G24: خامسًا: إقفال الفترة | H24: مخرَجُ المرحلة الخامسة مستندُ «الإقفال الشهري» بمعتمِدٍ هو مدير التشغيل — «ولا مرحلةَ بلا مخرَج»، والإقفالُ يمنع ما بعده. | I24: الشاشةُ فورمُ إدخالٍ عامٌّ (CMP-03) يكتب صفًّا واحدًا في جدولها الأصلي عبر `cmp03_store_insert()` بحالةٍ نصيةٍ يختارها المُدخِل؛ لا فعلَ اعتمادٍ ولا معتمِد، ولا قفلَ فترةٍ يمنع تعديلَ التايم شيت أو الإنتاج بعده، ولا حدثَ يُنشر، ولا أثرَ على المالية. | J24: Wrong Workflow | K24: P1 | L24: «الإقفالُ» تسميةٌ بلا مضمون: بعد حفظ صفِّ الإقفال تبقى بياناتُ الشهر قابلةً للتعديل والاعتماد، فلا يوجد في المنظومة لحظةٌ تُغلق فيها الفترةُ التشغيلية — وهو شرطُ صحةِ الإيراد والتكلفة الشهرية. | M24: توليدُ الشاشة ضمن دفعة فورمات CMP-03 (إدخالُ صفوفٍ فقط) بلا آلةِ حالةٍ ولا خدمةِ إقفالٍ خلفها. | N24: Operations/monthly_close.php:94; :100-103; :142; includes/cmp03_local_store.php:31; :55-60 | P24: ١) افتح Operations/monthly_close.php وأضِف صفَّ إقفالٍ لشهرٍ ما بحالة «مقفل». ٢) افتح Timesheet/timesheet.php وأضِف/عدّل سطرًا في الشهر نفسِه ⇒ يُقبل بلا منع. | Q24: أنشئ `app/Services/Operations/PeriodCloseService.php` بفعلَي `close()` و`reopen()` (بسببٍ ومعتمِد)، واربطها بجدول `period_locks(company_id, scope, period, state)`؛ واجعل `Operations/monthly_close.php` تستدعيها، وأضِف في حرّاس الكتابة (Timesheet · Operations · Contracts) فحصَ القفل قبل أيِّ كتابةٍ في فترةٍ مقفلة. | R24: فريق الباك-إند — وحدة التشغيل | S24: نعم | T24: نعم | U24: بعد إقفال شهرٍ يُرفض أيُّ تعديلٍ على تايم شيت أو إنتاجِ الشهر نفسِه برسالةٍ تسمّي الفترةَ ومن أقفلها؛ وفتحُ الفترة يتطلب سببًا ومعتمِدًا أعلى. | V24: مفتوح | W24: مؤكَّدة | X24: تحقّقت: الشاشةُ نموذجُ CMP-03 يكتب صفًّا واحدًا بحالةٍ يختارها المُدخِل عبر cmp03_store_insert، بلا فعلِ اعتمادٍ ولا قفلِ فترةٍ ولا حدث؛ ومعالجُ الـPOST (السطر ٩٤) يسبق حارسَ insidebar (السطر ١٤٢) فالكتابةُ بلا حارس. | Y24: P1 | Z24: نعم | AA24: نعم | AB24: 02_FRD | AC24: فجوة تنفيذ (Implementation) | AD24: Decision Closed · Implementation Open
... A64: INJ-0060 | B64: INJAZ-UX-01 | C64: §٦ الشاشاتُ وأعمدتُها · OBL-0052 «والحقلُ بلا صنفٍ لا يُدرَج في شاشةٍ حاكمة» | D64: إدارة الحوكمة والالتزام | E64: الشاشات المولَّدة بعُدّة u13 (٤٤ شاشة) | F64: http://localhost/ems/Audit/iaf_charter.php | G64: - | H64: «كلُّ حقلٍ يُوسَم بصنفٍ … والحقلُ بلا صنفٍ لا يُدرَج في شاشةٍ حاكمة» — والتصنيفُ شرطُ الظهور. | I64: نشرٌ من database/schema + database/migrations يترك gov_field_class فارغًا فتُصيَّر الشاشاتُ الأربعُ والأربعون برسالة «لا عمودَ مصنَّفٌ لهذه الشاشة» — فجوةُ بذرٍ في خط النشر لا عطبٌ في الشاشات. — [مُصحَّح بعد التحقق] الصياغة الأولى: أعمدةُ الشاشاتِ المولَّدةِ تُقرأ حصرًا من `gov_field_class` (`includes/u13_screen_kit.php:42-73`)، وإن خلا الجدولُ فلا عمودَ يُصيَّر وتُطبع الرسالةُ «لا عمودَ مصنَّفٌ لهذه الشاشة» (`:341-342`). والجدو | J64: Data Mismatch | K64: P1 | L64: أيُّ نشرٍ يبني القاعدةَ من `database/schema/` + `database/migrations/` يُنتج **أربعًا وأربعين شاشةً بلا أعمدةٍ إطلاقًا** — منها كلُّ شاشاتِ المراجعةِ الداخليةِ الستَّ عشرةَ وشاشاتِ الالتزاماتِ الماليةِ وشاشاتِ رئيسِ الحسابات. جداولُ فارغةٌ برأسٍ فارغ، والمستخدمُ يظنُّ الشاشةَ معطوبة. | M64: خطوةُ بذرٍ إلزاميةٌ خارجَ مسارِ النشرِ الآلي (أداةُ CLI) وبلا فحصٍ يمنع النشرَ عند خلوِّ الجدول. | N64: includes/u13_screen_kit.php:42-73,206-207,341-342; database/migrations/2026_12_24_u13_field_governance.sql:52-60; tools/u13_seed.php:802 | P64: ١) ابنِ قاعدةً جديدةً من `database/schema/schema.sql` + `seed_reference.sql` + كلِّ الهجرات. ٢) `SELECT COUNT(*) FROM gov_field_class` → صفر. ٣) افتح `Audit/iaf_charter.php` أو `Finance/ob_register.php`: جدولٌ بلا أعمدةٍ ورسالةُ «لا عمودَ مصنَّفٌ لهذه الشاشة». | Q64: حوِّل مخرَجَ `tools/u13_seed.php` إلى هجرةِ SQL ثابتةٍ داخلَ `database/migrations/` (أو صفوفٍ في `seed_reference.sql`) كي يُبذَر الجدولُ في كلِّ نشرٍ آليًّا؛ وأضِف فحصًا في `tools/u13_gate.php` يرسب إن كانت أيُّ شاشةٍ في البيانِ بلا صفوفٍ في `gov_field_class`. | R64: فريق الباك-إند — الحوكمة والمنصة | S64: نعم | T64: نعم | U64: بعد نشرٍ نظيفٍ من `database/` وحدَه: كلُّ شاشةٍ من الأربعِ والأربعين تعرض أعمدتَها المصنَّفة، و`SELECT COUNT(*) FROM gov_field_class` > 0. | V64: مفتوح | W64: مرجَّحة | X64: مؤكَّدٌ بالفحص: u13_columns (includes/u13_screen_kit.php:42-73) تُسقط كلَّ عمودٍ بلا صفٍّ في gov_field_class (:66 «بلا صنفٍ = لا يُصيَّر») وتُطبع رسالةَ الفراغ (:341-342)؛ وgov_field_class لا يرد في seed_reference.sql إطلاقًا، والهجرتان تُنشئان الجدولَ بلا INSERT، والمصدرُ الوحيد tools/u13_seed.php:802 بـ--apply ولا يستدعيه أيُّ سكربتِ نشر. لكنه فجوةُ بذرٍ في النشر تُصلَح بتشغيل أداةٍ واحدة، لا فقدانَ شاشةٍ أو مصدرِ حقيقة. | Y64: P0 | Z64: نعم | AA64: نعم | AB64: 03_UX | AC64: فجوة تنفيذ (Implementation) | AD64: Decision Closed · Implementation Open
A65: INJ-0061 | B65: INJAZ-UX-01 | C65: §٤-٥ · «الرابطُ الميت مستبعدٌ بنيويًّا لا برأي الشاشة» | D65: إدارة الحوكمة والالتزام | E65: السايدبار — مسارات نسبية مزدوجة | G65: - | H65: «الظهور = صفٌّ تابعٌ للدور في nav_items (active=1) **و** can_view=1 … الرابطُ الميت مستبعدٌ بنيويًّا» — والمسارُ في `nav_items` «المسارُ كما في سجلِّ الشاشات». | I65: كلُّ الصفوف الـ41 ذاتِ البادئة `../` تحمل أيضًا `module_id=NULL` مع `permission_code` غيرِ فارغٍ و`door='main'` — فيسقطها شرطُ `getUnifiedNavItems` ولا يُصيَّر أيٌّ منها في أيِّ سايدبار (41 شاشةَ update0013 محجوبةٌ كليًّا). — [مُصحَّح بعد التحقق] الصياغة الأولى: عمودُ `route` في `nav_items` غيرُ متجانس: ١٥٠٧ صفًّا بمسارٍ نسبيٍّ من جذرِ التطبيق (`Risk/risk_board.php`) و٤١ صفًّا بمسارٍ مسبوقٍ بـ`'../'` (`../Audit/iaf_charter.php`). و`printNavLinkItem` يضيف `$ba | J65: Broken Button | K65: P1 | L65: حتى لو صُحِّح البابُ فستُطبع واحدٌ وأربعون رابطًا مكسورًا (404) — إصلاحٌ نصفيٌّ سيُنتج عيبًا ظاهرًا للمستخدم. ويشير إلى غيابِ قيدِ صحةٍ على عمودِ المسار. | M65: أُدرجت الصفوفُ بهجرةٍ يدويةٍ نسخت المسارَ من `href` في الشاشةِ لا من سجلِّ الشاشات. | N65: database/schema/seed_reference.sql:5057; :5077; :5096; includes/dynamic_nav.php:320; includes/unified_nav.php:70-78 | P65: ١) `SELECT COUNT(*) FROM nav_items WHERE route LIKE '../%'` → ٤١. ٢) قارِنها بالصفوفِ الأخرى: بلا بادئة. ٣) اقرأ `includes/dynamic_nav.php:320`: البادئةُ تُضاف دائمًا. | Q65: نفِّذ `UPDATE nav_items SET route = TRIM(LEADING '../' FROM route) WHERE route LIKE '../%'`؛ وأضِف قيدَ فحصٍ (CHECK أو قادحًا) يمنع إدراجَ مسارٍ يبدأ بـ`../` أو `/`، وفحصًا في بوابةِ القبولِ يقارن `route` بـ`modules.code` ويرسب على الاختلاف. | R65: فريق الواجهة — وحدة التنقل | S65: نعم | T65: لا | U65: `SELECT COUNT(*) FROM nav_items WHERE route LIKE '../%' OR route NOT IN (SELECT code FROM modules)` = 0؛ وكلُّ رابطٍ في السايدبار يفتح صفحتَه بلا 404. | V65: مفتوح | W65: مؤكَّدة | X65: العددان مطابقان تمامًا (1507 مقابل 41)، و`printNavLinkItem` يضيف `$basePrefix` دائمًا؛ بل الأسوأُ أن الصفوفَ الأربعين لا تُطبع أصلًا فتختفي الشاشاتُ الجديدةُ كليًّا. | Y65: P1 | Z65: لا — يحتاج مراجعة | AA65: نعم | AB65: 03_UX | AC65: فجوة تنفيذ (Implementation) | AD65: Decision Closed · Implementation Open
